<<< -- process set (n=8) with 6 CPU-bound processes
<<< -- seed=768; lambda=0.001000; bound=1024

CPU-bound process A0: arrival time 54ms; 29 CPU bursts:
==> CPU burst 3764ms ==> I/O burst 686ms
==> CPU burst 1732ms ==> I/O burst 212ms
==> CPU burst 844ms ==> I/O burst 493ms
==> CPU burst 168ms ==> I/O burst 372ms
==> CPU burst 736ms ==> I/O burst 141ms
==> CPU burst 1372ms ==> I/O burst 554ms
==> CPU burst 1808ms ==> I/O burst 149ms
==> CPU burst 1808ms ==> I/O burst 266ms
==> CPU burst 848ms ==> I/O burst 75ms
==> CPU burst 3384ms ==> I/O burst 17ms
==> CPU burst 104ms ==> I/O burst 428ms
==> CPU burst 3924ms ==> I/O burst 667ms
==> CPU burst 3388ms ==> I/O burst 94ms
==> CPU burst 100ms ==> I/O burst 487ms
==> CPU burst 3868ms ==> I/O burst 112ms
==> CPU burst 1516ms ==> I/O burst 311ms
==> CPU burst 1260ms ==> I/O burst 413ms
==> CPU burst 728ms ==> I/O burst 773ms
==> CPU burst 2568ms ==> I/O burst 348ms
==> CPU burst 1220ms ==> I/O burst 883ms
==> CPU burst 2296ms ==> I/O burst 664ms
==> CPU burst 3268ms ==> I/O burst 923ms
==> CPU burst 3468ms ==> I/O burst 288ms
==> CPU burst 2392ms ==> I/O burst 108ms
==> CPU burst 1976ms ==> I/O burst 564ms
==> CPU burst 312ms ==> I/O burst 545ms
==> CPU burst 1440ms ==> I/O burst 136ms
==> CPU burst 3052ms ==> I/O burst 558ms
==> CPU burst 2044ms

CPU-bound process A1: arrival time 56ms; 31 CPU bursts:
==> CPU burst 2828ms ==> I/O burst 322ms
==> CPU burst 1444ms ==> I/O burst 167ms
==> CPU burst 2476ms ==> I/O burst 417ms
==> CPU burst 2256ms ==> I/O burst 290ms
==> CPU burst 1188ms ==> I/O burst 777ms
==> CPU burst 2812ms ==> I/O burst 863ms
==> CPU burst 368ms ==> I/O burst 173ms
==> CPU burst 200ms ==> I/O burst 607ms
==> CPU burst 1044ms ==> I/O burst 592ms
==> CPU burst 940ms ==> I/O burst 445ms
==> CPU burst 660ms ==> I/O burst 28ms
==> CPU burst 2196ms ==> I/O burst 976ms
==> CPU burst 36ms ==> I/O burst 637ms
==> CPU burst 4060ms ==> I/O burst 90ms
==> CPU burst 3904ms ==> I/O burst 534ms
==> CPU burst 1488ms ==> I/O burst 404ms
==> CPU burst 1080ms ==> I/O burst 51ms
==> CPU burst 916ms ==> I/O burst 71ms
==> CPU burst 3724ms ==> I/O burst 111ms
==> CPU burst 1764ms ==> I/O burst 282ms
==> CPU burst 860ms ==> I/O burst 99ms
==> CPU burst 2700ms ==> I/O burst 767ms
==> CPU burst 100ms ==> I/O burst 586ms
==> CPU burst 420ms ==> I/O burst 709ms
==> CPU burst 3504ms ==> I/O burst 671ms
==> CPU burst 3504ms ==> I/O burst 334ms
==> CPU burst 2352ms ==> I/O burst 251ms
==> CPU burst 2652ms ==> I/O burst 768ms
==> CPU burst 3812ms ==> I/O burst 527ms
==> CPU burst 2288ms ==> I/O burst 166ms
==> CPU burst 388ms

CPU-bound process A2: arrival time 456ms; 9 CPU bursts:
==> CPU burst 1896ms ==> I/O burst 618ms
==> CPU burst 2940ms ==> I/O burst 439ms
==> CPU burst 248ms ==> I/O burst 464ms
==> CPU burst 952ms ==> I/O burst 774ms
==> CPU burst 1796ms ==> I/O burst 411ms
==> CPU burst 2200ms ==> I/O burst 15ms
==> CPU burst 1512ms ==> I/O burst 787ms
==> CPU burst 1764ms ==> I/O burst 84ms
==> CPU burst 1768ms

CPU-bound process A3: arrival time 758ms; 16 CPU bursts:
==> CPU burst 548ms ==> I/O burst 799ms
==> CPU burst 428ms ==> I/O burst 938ms
==> CPU burst 1432ms ==> I/O burst 317ms
==> CPU burst 3896ms ==> I/O burst 124ms
==> CPU burst 804ms ==> I/O burst 65ms
==> CPU burst 2564ms ==> I/O burst 380ms
==> CPU burst 3416ms ==> I/O burst 889ms
==> CPU burst 3756ms ==> I/O burst 651ms
==> CPU burst 3864ms ==> I/O burst 423ms
==> CPU burst 1144ms ==> I/O burst 150ms
==> CPU burst 492ms ==> I/O burst 368ms
==> CPU burst 2704ms ==> I/O burst 176ms
==> CPU burst 316ms ==> I/O burst 668ms
==> CPU burst 204ms ==> I/O burst 332ms
==> CPU burst 2328ms ==> I/O burst 896ms
==> CPU burst 2760ms

CPU-bound process A4: arrival time 346ms; 2 CPU bursts:
==> CPU burst 2428ms ==> I/O burst 509ms
==> CPU burst 2532ms

CPU-bound process A5: arrival time 115ms; 1 CPU burst:
==> CPU burst 564ms

I/O-bound process A6: arrival time 242ms; 27 CPU bursts:
==> CPU burst 761ms ==> I/O burst 2264ms
==> CPU burst 903ms ==> I/O burst 2048ms
==> CPU burst 303ms ==> I/O burst 7328ms
==> CPU burst 194ms ==> I/O burst 6896ms
==> CPU burst 203ms ==> I/O burst 2800ms
==> CPU burst 603ms ==> I/O burst 3064ms
==> CPU burst 95ms ==> I/O burst 1056ms
==> CPU burst 556ms ==> I/O burst 3376ms
==> CPU burst 599ms ==> I/O burst 560ms
==> CPU burst 58ms ==> I/O burst 2056ms
==> CPU burst 455ms ==> I/O burst 3112ms
==> CPU burst 826ms ==> I/O burst 2640ms
==> CPU burst 587ms ==> I/O burst 1920ms
==> CPU burst 292ms ==> I/O burst 4480ms
==> CPU burst 572ms ==> I/O burst 520ms
==> CPU burst 494ms ==> I/O burst 7088ms
==> CPU burst 19ms ==> I/O burst 4216ms
==> CPU burst 355ms ==> I/O burst 2968ms
==> CPU burst 81ms ==> I/O burst 7440ms
==> CPU burst 25ms ==> I/O burst 944ms
==> CPU burst 445ms ==> I/O burst 3208ms
==> CPU burst 35ms ==> I/O burst 3040ms
==> CPU burst 245ms ==> I/O burst 7240ms
==> CPU burst 732ms ==> I/O burst 2064ms
==> CPU burst 850ms ==> I/O burst 6800ms
==> CPU burst 667ms ==> I/O burst 248ms
==> CPU burst 370ms

I/O-bound process A7: arrival time 357ms; 21 CPU bursts:
==> CPU burst 297ms ==> I/O burst 7864ms
==> CPU burst 598ms ==> I/O burst 2456ms
==> CPU burst 721ms ==> I/O burst 2736ms
==> CPU burst 641ms ==> I/O burst 1944ms
==> CPU burst 128ms ==> I/O burst 6168ms
==> CPU burst 277ms ==> I/O burst 848ms
==> CPU burst 984ms ==> I/O burst 5208ms
==> CPU burst 961ms ==> I/O burst 3432ms
==> CPU burst 587ms ==> I/O burst 792ms
==> CPU burst 33ms ==> I/O burst 2584ms
==> CPU burst 875ms ==> I/O burst 2352ms
==> CPU burst 53ms ==> I/O burst 240ms
==> CPU burst 64ms ==> I/O burst 3496ms
==> CPU burst 264ms ==> I/O burst 1048ms
==> CPU burst 228ms ==> I/O burst 2264ms
==> CPU burst 37ms ==> I/O burst 5496ms
==> CPU burst 364ms ==> I/O burst 4312ms
==> CPU burst 278ms ==> I/O burst 2512ms
==> CPU burst 23ms ==> I/O burst 7880ms
==> CPU burst 188ms ==> I/O burst 3896ms
==> CPU burst 214ms

<<< PROJECT SIMULATIONS
<<< -- t_cs=6ms; alpha=0.95; t_slice=128ms
time 0ms: Simulator started for FCFS [Q empty]
time 54ms: Process A0 arrived; added to ready queue [Q A0]
time 56ms: Process A1 arrived; added to ready queue [Q A1]
time 57ms: Process A0 started using the CPU for 3764ms burst [Q A1]
time 115ms: Process A5 arrived; added to ready queue [Q A1 A5]
time 242ms: Process A6 arrived; added to ready queue [Q A1 A5 A6]
time 346ms: Process A4 arrived; added to ready queue [Q A1 A5 A6 A4]
time 357ms: Process A7 arrived; added to ready queue [Q A1 A5 A6 A4 A7]
time 456ms: Process A2 arrived; added to ready queue [Q A1 A5 A6 A4 A7 A2]
time 758ms: Process A3 arrived; added to ready queue [Q A1 A5 A6 A4 A7 A2 A3]
time 3821ms: Process A0 completed a CPU burst; 28 bursts to go [Q A1 A5 A6 A4 A7 A2 A3]
time 3821ms: Process A0 switching out of CPU; blocking on I/O until time 4510ms [Q A1 A5 A6 A4 A7 A2 A3]
time 3827ms: Process A1 started using the CPU for 2828ms burst [Q A5 A6 A4 A7 A2 A3]
time 4510ms: Process A0 completed I/O; added to ready queue [Q A5 A6 A4 A7 A2 A3 A0]
time 6655ms: Process A1 completed a CPU burst; 30 bursts to go [Q A5 A6 A4 A7 A2 A3 A0]
time 6655ms: Process A1 switching out of CPU; blocking on I/O until time 6980ms [Q A5 A6 A4 A7 A2 A3 A0]
time 6661ms: Process A5 started using the CPU for 564ms burst [Q A6 A4 A7 A2 A3 A0]
time 6980ms: Process A1 completed I/O; added to ready queue [Q A6 A4 A7 A2 A3 A0 A1]
time 7225ms: Process A5 terminated [Q A6 A4 A7 A2 A3 A0 A1]
time 7231ms: Process A6 started using the CPU for 761ms burst [Q A4 A7 A2 A3 A0 A1]
time 7992ms: Process A6 completed a CPU burst; 26 bursts to go [Q A4 A7 A2 A3 A0 A1]
time 7992ms: Process A6 switching out of CPU; blocking on I/O until time 10259ms [Q A4 A7 A2 A3 A0 A1]
time 7998ms: Process A4 started using the CPU for 2428ms burst [Q A7 A2 A3 A0 A1]
time 10259ms: Process A6 completed I/O; added to ready queue [Q A7 A2 A3 A0 A1 A6]
time 10426ms: Process A4 completed a CPU burst; 1 burst to go [Q A7 A2 A3 A0 A1 A6]
time 10426ms: Process A4 switching out of CPU; blocking on I/O until time 10938ms [Q A7 A2 A3 A0 A1 A6]
time 10432ms: Process A7 started using the CPU for 297ms burst [Q A2 A3 A0 A1 A6]
time 10729ms: Process A7 completed a CPU burst; 20 bursts to go [Q A2 A3 A0 A1 A6]
time 10729ms: Process A7 switching out of CPU; blocking on I/O until time 18596ms [Q A2 A3 A0 A1 A6]
time 10735ms: Process A2 started using the CPU for 1896ms burst [Q A3 A0 A1 A6]
time 10938ms: Process A4 completed I/O; added to ready queue [Q A3 A0 A1 A6 A4]
time 12631ms: Process A2 completed a CPU burst; 8 bursts to go [Q A3 A0 A1 A6 A4]
time 12631ms: Process A2 switching out of CPU; blocking on I/O until time 13252ms [Q A3 A0 A1 A6 A4]
time 12637ms: Process A3 started using the CPU for 548ms burst [Q A0 A1 A6 A4]
time 13185ms: Process A3 completed a CPU burst; 15 bursts to go [Q A0 A1 A6 A4]
time 13185ms: Process A3 switching out of CPU; blocking on I/O until time 13987ms [Q A0 A1 A6 A4]
time 13191ms: Process A0 started using the CPU for 1732ms burst [Q A1 A6 A4]
time 13252ms: Process A2 completed I/O; added to ready queue [Q A1 A6 A4 A2]
time 13987ms: Process A3 completed I/O; added to ready queue [Q A1 A6 A4 A2 A3]
time 14923ms: Process A0 completed a CPU burst; 27 bursts to go [Q A1 A6 A4 A2 A3]
time 14923ms: Process A0 switching out of CPU; blocking on I/O until time 15138ms [Q A1 A6 A4 A2 A3]
time 14929ms: Process A1 started using the CPU for 1444ms burst [Q A6 A4 A2 A3]
time 15138ms: Process A0 completed I/O; added to ready queue [Q A6 A4 A2 A3 A0]
time 16373ms: Process A1 completed a CPU burst; 29 bursts to go [Q A6 A4 A2 A3 A0]
time 16373ms: Process A1 switching out of CPU; blocking on I/O until time 16543ms [Q A6 A4 A2 A3 A0]
time 16379ms: Process A6 started using the CPU for 903ms burst [Q A4 A2 A3 A0]
time 16543ms: Process A1 completed I/O; added to ready queue [Q A4 A2 A3 A0 A1]
time 17282ms: Process A6 completed a CPU burst; 25 bursts to go [Q A4 A2 A3 A0 A1]
time 17282ms: Process A6 switching out of CPU; blocking on I/O until time 19333ms [Q A4 A2 A3 A0 A1]
time 17288ms: Process A4 started using the CPU for 2532ms burst [Q A2 A3 A0 A1]
time 18596ms: Process A7 completed I/O; added to ready queue [Q A2 A3 A0 A1 A7]
time 19333ms: Process A6 completed I/O; added to ready queue [Q A2 A3 A0 A1 A7 A6]
time 19820ms: Process A4 terminated [Q A2 A3 A0 A1 A7 A6]
time 19826ms: Process A2 started using the CPU for 2940ms burst [Q A3 A0 A1 A7 A6]
time 22766ms: Process A2 completed a CPU burst; 7 bursts to go [Q A3 A0 A1 A7 A6]
time 22766ms: Process A2 switching out of CPU; blocking on I/O until time 23208ms [Q A3 A0 A1 A7 A6]
time 22772ms: Process A3 started using the CPU for 428ms burst [Q A0 A1 A7 A6]
time 23200ms: Process A3 completed a CPU burst; 14 bursts to go [Q A0 A1 A7 A6]
time 23200ms: Process A3 switching out of CPU; blocking on I/O until time 24141ms [Q A0 A1 A7 A6]
time 23206ms: Process A0 started using the CPU for 844ms burst [Q A1 A7 A6]
time 23208ms: Process A2 completed I/O; added to ready queue [Q A1 A7 A6 A2]
time 24050ms: Process A0 completed a CPU burst; 26 bursts to go [Q A1 A7 A6 A2]
time 24050ms: Process A0 switching out of CPU; blocking on I/O until time 24546ms [Q A1 A7 A6 A2]
time 24056ms: Process A1 started using the CPU for 2476ms burst [Q A7 A6 A2]
time 24141ms: Process A3 completed I/O; added to ready queue [Q A7 A6 A2 A3]
time 24546ms: Process A0 completed I/O; added to ready queue [Q A7 A6 A2 A3 A0]
time 26532ms: Process A1 completed a CPU burst; 28 bursts to go [Q A7 A6 A2 A3 A0]
time 26532ms: Process A1 switching out of CPU; blocking on I/O until time 26952ms [Q A7 A6 A2 A3 A0]
time 26538ms: Process A7 started using the CPU for 598ms burst [Q A6 A2 A3 A0]
time 26952ms: Process A1 completed I/O; added to ready queue [Q A6 A2 A3 A0 A1]
time 27136ms: Process A7 completed a CPU burst; 19 bursts to go [Q A6 A2 A3 A0 A1]
time 27136ms: Process A7 switching out of CPU; blocking on I/O until time 29595ms [Q A6 A2 A3 A0 A1]
time 27142ms: Process A6 started using the CPU for 303ms burst [Q A2 A3 A0 A1]
time 27445ms: Process A6 completed a CPU burst; 24 bursts to go [Q A2 A3 A0 A1]
time 27445ms: Process A6 switching out of CPU; blocking on I/O until time 34776ms [Q A2 A3 A0 A1]
time 27451ms: Process A2 started using the CPU for 248ms burst [Q A3 A0 A1]
time 27699ms: Process A2 completed a CPU burst; 6 bursts to go [Q A3 A0 A1]
time 27699ms: Process A2 switching out of CPU; blocking on I/O until time 28166ms [Q A3 A0 A1]
time 27705ms: Process A3 started using the CPU for 1432ms burst [Q A0 A1]
time 28166ms: Process A2 completed I/O; added to ready queue [Q A0 A1 A2]
time 29137ms: Process A3 completed a CPU burst; 13 bursts to go [Q A0 A1 A2]
time 29137ms: Process A3 switching out of CPU; blocking on I/O until time 29457ms [Q A0 A1 A2]
time 29143ms: Process A0 started using the CPU for 168ms burst [Q A1 A2]
time 29311ms: Process A0 completed a CPU burst; 25 bursts to go [Q A1 A2]
time 29311ms: Process A0 switching out of CPU; blocking on I/O until time 29686ms [Q A1 A2]
time 29317ms: Process A1 started using the CPU for 2256ms burst [Q A2]
time 29457ms: Process A3 completed I/O; added to ready queue [Q A2 A3]
time 29595ms: Process A7 completed I/O; added to ready queue [Q A2 A3 A7]
time 29686ms: Process A0 completed I/O; added to ready queue [Q A2 A3 A7 A0]
time 31573ms: Process A1 completed a CPU burst; 27 bursts to go [Q A2 A3 A7 A0]
time 31573ms: Process A1 switching out of CPU; blocking on I/O until time 31866ms [Q A2 A3 A7 A0]
time 31579ms: Process A2 started using the CPU for 952ms burst [Q A3 A7 A0]
time 31866ms: Process A1 completed I/O; added to ready queue [Q A3 A7 A0 A1]
time 32531ms: Process A2 completed a CPU burst; 5 bursts to go [Q A3 A7 A0 A1]
time 32531ms: Process A2 switching out of CPU; blocking on I/O until time 33308ms [Q A3 A7 A0 A1]
time 32537ms: Process A3 started using the CPU for 3896ms burst [Q A7 A0 A1]
time 33308ms: Process A2 completed I/O; added to ready queue [Q A7 A0 A1 A2]
time 34776ms: Process A6 completed I/O; added to ready queue [Q A7 A0 A1 A2 A6]
time 36433ms: Process A3 completed a CPU burst; 12 bursts to go [Q A7 A0 A1 A2 A6]
time 36433ms: Process A3 switching out of CPU; blocking on I/O until time 36560ms [Q A7 A0 A1 A2 A6]
time 36439ms: Process A7 started using the CPU for 721ms burst [Q A0 A1 A2 A6]
time 36560ms: Process A3 completed I/O; added to ready queue [Q A0 A1 A2 A6 A3]
time 37160ms: Process A7 completed a CPU burst; 18 bursts to go [Q A0 A1 A2 A6 A3]
time 37160ms: Process A7 switching out of CPU; blocking on I/O until time 39899ms [Q A0 A1 A2 A6 A3]
time 37166ms: Process A0 started using the CPU for 736ms burst [Q A1 A2 A6 A3]
time 37902ms: Process A0 completed a CPU burst; 24 bursts to go [Q A1 A2 A6 A3]
time 37902ms: Process A0 switching out of CPU; blocking on I/O until time 38046ms [Q A1 A2 A6 A3]
time 37908ms: Process A1 started using the CPU for 1188ms burst [Q A2 A6 A3]
time 38046ms: Process A0 completed I/O; added to ready queue [Q A2 A6 A3 A0]
time 39096ms: Process A1 completed a CPU burst; 26 bursts to go [Q A2 A6 A3 A0]
time 39096ms: Process A1 switching out of CPU; blocking on I/O until time 39876ms [Q A2 A6 A3 A0]
time 39102ms: Process A2 started using the CPU for 1796ms burst [Q A6 A3 A0]
time 39876ms: Process A1 completed I/O; added to ready queue [Q A6 A3 A0 A1]
time 39899ms: Process A7 completed I/O; added to ready queue [Q A6 A3 A0 A1 A7]
time 40898ms: Process A2 completed a CPU burst; 4 bursts to go [Q A6 A3 A0 A1 A7]
time 40898ms: Process A2 switching out of CPU; blocking on I/O until time 41312ms [Q A6 A3 A0 A1 A7]
time 40904ms: Process A6 started using the CPU for 194ms burst [Q A3 A0 A1 A7]
time 41098ms: Process A6 completed a CPU burst; 23 bursts to go [Q A3 A0 A1 A7]
time 41098ms: Process A6 switching out of CPU; blocking on I/O until time 47997ms [Q A3 A0 A1 A7]
time 41104ms: Process A3 started using the CPU for 804ms burst [Q A0 A1 A7]
time 41312ms: Process A2 completed I/O; added to ready queue [Q A0 A1 A7 A2]
time 41908ms: Process A3 completed a CPU burst; 11 bursts to go [Q A0 A1 A7 A2]
time 41908ms: Process A3 switching out of CPU; blocking on I/O until time 41976ms [Q A0 A1 A7 A2]
time 41914ms: Process A0 started using the CPU for 1372ms burst [Q A1 A7 A2]
time 41976ms: Process A3 completed I/O; added to ready queue [Q A1 A7 A2 A3]
time 43286ms: Process A0 completed a CPU burst; 23 bursts to go [Q A1 A7 A2 A3]
time 43286ms: Process A0 switching out of CPU; blocking on I/O until time 43843ms [Q A1 A7 A2 A3]
time 43292ms: Process A1 started using the CPU for 2812ms burst [Q A7 A2 A3]
time 43843ms: Process A0 completed I/O; added to ready queue [Q A7 A2 A3 A0]
time 46104ms: Process A1 completed a CPU burst; 25 bursts to go [Q A7 A2 A3 A0]
time 46104ms: Process A1 switching out of CPU; blocking on I/O until time 46970ms [Q A7 A2 A3 A0]
time 46110ms: Process A7 started using the CPU for 641ms burst [Q A2 A3 A0]
time 46751ms: Process A7 completed a CPU burst; 17 bursts to go [Q A2 A3 A0]
time 46751ms: Process A7 switching out of CPU; blocking on I/O until time 48698ms [Q A2 A3 A0]
time 46757ms: Process A2 started using the CPU for 2200ms burst [Q A3 A0]
time 46970ms: Process A1 completed I/O; added to ready queue [Q A3 A0 A1]
time 47997ms: Process A6 completed I/O; added to ready queue [Q A3 A0 A1 A6]
time 48698ms: Process A7 completed I/O; added to ready queue [Q A3 A0 A1 A6 A7]
time 48957ms: Process A2 completed a CPU burst; 3 bursts to go [Q A3 A0 A1 A6 A7]
time 48957ms: Process A2 switching out of CPU; blocking on I/O until time 48975ms [Q A3 A0 A1 A6 A7]
time 48963ms: Process A3 started using the CPU for 2564ms burst [Q A0 A1 A6 A7]
time 48975ms: Process A2 completed I/O; added to ready queue [Q A0 A1 A6 A7 A2]
time 51527ms: Process A3 completed a CPU burst; 10 bursts to go [Q A0 A1 A6 A7 A2]
time 51527ms: Process A3 switching out of CPU; blocking on I/O until time 51910ms [Q A0 A1 A6 A7 A2]
time 51533ms: Process A0 started using the CPU for 1808ms burst [Q A1 A6 A7 A2]
time 51910ms: Process A3 completed I/O; added to ready queue [Q A1 A6 A7 A2 A3]
time 53341ms: Process A0 completed a CPU burst; 22 bursts to go [Q A1 A6 A7 A2 A3]
time 53341ms: Process A0 switching out of CPU; blocking on I/O until time 53493ms [Q A1 A6 A7 A2 A3]
time 53347ms: Process A1 started using the CPU for 368ms burst [Q A6 A7 A2 A3]
time 53493ms: Process A0 completed I/O; added to ready queue [Q A6 A7 A2 A3 A0]
time 53715ms: Process A1 completed a CPU burst; 24 bursts to go [Q A6 A7 A2 A3 A0]
time 53715ms: Process A1 switching out of CPU; blocking on I/O until time 53891ms [Q A6 A7 A2 A3 A0]
time 53721ms: Process A6 started using the CPU for 203ms burst [Q A7 A2 A3 A0]
time 53891ms: Process A1 completed I/O; added to ready queue [Q A7 A2 A3 A0 A1]
time 53924ms: Process A6 completed a CPU burst; 22 bursts to go [Q A7 A2 A3 A0 A1]
time 53924ms: Process A6 switching out of CPU; blocking on I/O until time 56727ms [Q A7 A2 A3 A0 A1]
time 53930ms: Process A7 started using the CPU for 128ms burst [Q A2 A3 A0 A1]
time 54058ms: Process A7 completed a CPU burst; 16 bursts to go [Q A2 A3 A0 A1]
time 54058ms: Process A7 switching out of CPU; blocking on I/O until time 60229ms [Q A2 A3 A0 A1]
time 54064ms: Process A2 started using the CPU for 1512ms burst [Q A3 A0 A1]
time 55576ms: Process A2 completed a CPU burst; 2 bursts to go [Q A3 A0 A1]
time 55576ms: Process A2 switching out of CPU; blocking on I/O until time 56366ms [Q A3 A0 A1]
time 55582ms: Process A3 started using the CPU for 3416ms burst [Q A0 A1]
time 56366ms: Process A2 completed I/O; added to ready queue [Q A0 A1 A2]
time 56727ms: Process A6 completed I/O; added to ready queue [Q A0 A1 A2 A6]
time 58998ms: Process A3 completed a CPU burst; 9 bursts to go [Q A0 A1 A2 A6]
time 58998ms: Process A3 switching out of CPU; blocking on I/O until time 59890ms [Q A0 A1 A2 A6]
time 59004ms: Process A0 started using the CPU for 1808ms burst [Q A1 A2 A6]
time 59890ms: Process A3 completed I/O; added to ready queue [Q A1 A2 A6 A3]
time 60229ms: Process A7 completed I/O; added to ready queue [Q A1 A2 A6 A3 A7]
time 60812ms: Process A0 completed a CPU burst; 21 bursts to go [Q A1 A2 A6 A3 A7]
time 60812ms: Process A0 switching out of CPU; blocking on I/O until time 61081ms [Q A1 A2 A6 A3 A7]
time 60818ms: Process A1 started using the CPU for 200ms burst [Q A2 A6 A3 A7]
time 61018ms: Process A1 completed a CPU burst; 23 bursts to go [Q A2 A6 A3 A7]
time 61018ms: Process A1 switching out of CPU; blocking on I/O until time 61628ms [Q A2 A6 A3 A7]
time 61024ms: Process A2 started using the CPU for 1764ms burst [Q A6 A3 A7]
time 61081ms: Process A0 completed I/O; added to ready queue [Q A6 A3 A7 A0]
time 61628ms: Process A1 completed I/O; added to ready queue [Q A6 A3 A7 A0 A1]
time 62788ms: Process A2 completed a CPU burst; 1 burst to go [Q A6 A3 A7 A0 A1]
time 62788ms: Process A2 switching out of CPU; blocking on I/O until time 62875ms [Q A6 A3 A7 A0 A1]
time 62794ms: Process A6 started using the CPU for 603ms burst [Q A3 A7 A0 A1]
time 62875ms: Process A2 completed I/O; added to ready queue [Q A3 A7 A0 A1 A2]
time 63397ms: Process A6 completed a CPU burst; 21 bursts to go [Q A3 A7 A0 A1 A2]
time 63397ms: Process A6 switching out of CPU; blocking on I/O until time 66464ms [Q A3 A7 A0 A1 A2]
time 63403ms: Process A3 started using the CPU for 3756ms burst [Q A7 A0 A1 A2]
time 66464ms: Process A6 completed I/O; added to ready queue [Q A7 A0 A1 A2 A6]
time 67159ms: Process A3 completed a CPU burst; 8 bursts to go [Q A7 A0 A1 A2 A6]
time 67159ms: Process A3 switching out of CPU; blocking on I/O until time 67813ms [Q A7 A0 A1 A2 A6]
time 67165ms: Process A7 started using the CPU for 277ms burst [Q A0 A1 A2 A6]
time 67442ms: Process A7 completed a CPU burst; 15 bursts to go [Q A0 A1 A2 A6]
time 67442ms: Process A7 switching out of CPU; blocking on I/O until time 68293ms [Q A0 A1 A2 A6]
time 67448ms: Process A0 started using the CPU for 848ms burst [Q A1 A2 A6]
time 67813ms: Process A3 completed I/O; added to ready queue [Q A1 A2 A6 A3]
time 68293ms: Process A7 completed I/O; added to ready queue [Q A1 A2 A6 A3 A7]
time 68296ms: Process A0 completed a CPU burst; 20 bursts to go [Q A1 A2 A6 A3 A7]
time 68296ms: Process A0 switching out of CPU; blocking on I/O until time 68374ms [Q A1 A2 A6 A3 A7]
time 68302ms: Process A1 started using the CPU for 1044ms burst [Q A2 A6 A3 A7]
time 68374ms: Process A0 completed I/O; added to ready queue [Q A2 A6 A3 A7 A0]
time 69346ms: Process A1 completed a CPU burst; 22 bursts to go [Q A2 A6 A3 A7 A0]
time 69346ms: Process A1 switching out of CPU; blocking on I/O until time 69941ms [Q A2 A6 A3 A7 A0]
time 69352ms: Process A2 started using the CPU for 1768ms burst [Q A6 A3 A7 A0]
time 69941ms: Process A1 completed I/O; added to ready queue [Q A6 A3 A7 A0 A1]
time 71120ms: Process A2 terminated [Q A6 A3 A7 A0 A1]
time 71126ms: Process A6 started using the CPU for 95ms burst [Q A3 A7 A0 A1]
time 71221ms: Process A6 completed a CPU burst; 20 bursts to go [Q A3 A7 A0 A1]
time 71221ms: Process A6 switching out of CPU; blocking on I/O until time 72280ms [Q A3 A7 A0 A1]
time 71227ms: Process A3 started using the CPU for 3864ms burst [Q A7 A0 A1]
time 72280ms: Process A6 completed I/O; added to ready queue [Q A7 A0 A1 A6]
time 75091ms: Process A3 completed a CPU burst; 7 bursts to go [Q A7 A0 A1 A6]
time 75091ms: Process A3 switching out of CPU; blocking on I/O until time 75517ms [Q A7 A0 A1 A6]
time 75097ms: Process A7 started using the CPU for 984ms burst [Q A0 A1 A6]
time 75517ms: Process A3 completed I/O; added to ready queue [Q A0 A1 A6 A3]
time 76081ms: Process A7 completed a CPU burst; 14 bursts to go [Q A0 A1 A6 A3]
time 76081ms: Process A7 switching out of CPU; blocking on I/O until time 81292ms [Q A0 A1 A6 A3]
time 76087ms: Process A0 started using the CPU for 3384ms burst [Q A1 A6 A3]
time 79471ms: Process A0 completed a CPU burst; 19 bursts to go [Q A1 A6 A3]
time 79471ms: Process A0 switching out of CPU; blocking on I/O until time 79491ms [Q A1 A6 A3]
time 79477ms: Process A1 started using the CPU for 940ms burst [Q A6 A3]
time 79491ms: Process A0 completed I/O; added to ready queue [Q A6 A3 A0]
time 80417ms: Process A1 completed a CPU burst; 21 bursts to go [Q A6 A3 A0]
time 80417ms: Process A1 switching out of CPU; blocking on I/O until time 80865ms [Q A6 A3 A0]
time 80423ms: Process A6 started using the CPU for 556ms burst [Q A3 A0]
time 80865ms: Process A1 completed I/O; added to ready queue [Q A3 A0 A1]
time 80979ms: Process A6 completed a CPU burst; 19 bursts to go [Q A3 A0 A1]
time 80979ms: Process A6 switching out of CPU; blocking on I/O until time 84358ms [Q A3 A0 A1]
time 80985ms: Process A3 started using the CPU for 1144ms burst [Q A0 A1]
time 81292ms: Process A7 completed I/O; added to ready queue [Q A0 A1 A7]
time 82129ms: Process A3 completed a CPU burst; 6 bursts to go [Q A0 A1 A7]
time 82129ms: Process A3 switching out of CPU; blocking on I/O until time 82282ms [Q A0 A1 A7]
time 82135ms: Process A0 started using the CPU for 104ms burst [Q A1 A7]
time 82239ms: Process A0 completed a CPU burst; 18 bursts to go [Q A1 A7]
time 82239ms: Process A0 switching out of CPU; blocking on I/O until time 82670ms [Q A1 A7]
time 82245ms: Process A1 started using the CPU for 660ms burst [Q A7]
time 82282ms: Process A3 completed I/O; added to ready queue [Q A7 A3]
time 82670ms: Process A0 completed I/O; added to ready queue [Q A7 A3 A0]
time 82905ms: Process A1 completed a CPU burst; 20 bursts to go [Q A7 A3 A0]
time 82905ms: Process A1 switching out of CPU; blocking on I/O until time 82936ms [Q A7 A3 A0]
time 82911ms: Process A7 started using the CPU for 961ms burst [Q A3 A0]
time 82936ms: Process A1 completed I/O; added to ready queue [Q A3 A0 A1]
time 83872ms: Process A7 completed a CPU burst; 13 bursts to go [Q A3 A0 A1]
time 83872ms: Process A7 switching out of CPU; blocking on I/O until time 87307ms [Q A3 A0 A1]
time 83878ms: Process A3 started using the CPU for 492ms burst [Q A0 A1]
time 84358ms: Process A6 completed I/O; added to ready queue [Q A0 A1 A6]
time 84370ms: Process A3 completed a CPU burst; 5 bursts to go [Q A0 A1 A6]
time 84370ms: Process A3 switching out of CPU; blocking on I/O until time 84741ms [Q A0 A1 A6]
time 84376ms: Process A0 started using the CPU for 3924ms burst [Q A1 A6]
time 84741ms: Process A3 completed I/O; added to ready queue [Q A1 A6 A3]
time 87307ms: Process A7 completed I/O; added to ready queue [Q A1 A6 A3 A7]
time 88300ms: Process A0 completed a CPU burst; 17 bursts to go [Q A1 A6 A3 A7]
time 88300ms: Process A0 switching out of CPU; blocking on I/O until time 88970ms [Q A1 A6 A3 A7]
time 88306ms: Process A1 started using the CPU for 2196ms burst [Q A6 A3 A7]
time 88970ms: Process A0 completed I/O; added to ready queue [Q A6 A3 A7 A0]
time 90502ms: Process A1 completed a CPU burst; 19 bursts to go [Q A6 A3 A7 A0]
time 90502ms: Process A1 switching out of CPU; blocking on I/O until time 91481ms [Q A6 A3 A7 A0]
time 90508ms: Process A6 started using the CPU for 599ms burst [Q A3 A7 A0]
time 91107ms: Process A6 completed a CPU burst; 18 bursts to go [Q A3 A7 A0]
time 91107ms: Process A6 switching out of CPU; blocking on I/O until time 91670ms [Q A3 A7 A0]
time 91113ms: Process A3 started using the CPU for 2704ms burst [Q A7 A0]
time 91481ms: Process A1 completed I/O; added to ready queue [Q A7 A0 A1]
time 91670ms: Process A6 completed I/O; added to ready queue [Q A7 A0 A1 A6]
time 93817ms: Process A3 completed a CPU burst; 4 bursts to go [Q A7 A0 A1 A6]
time 93817ms: Process A3 switching out of CPU; blocking on I/O until time 93996ms [Q A7 A0 A1 A6]
time 93823ms: Process A7 started using the CPU for 587ms burst [Q A0 A1 A6]
time 93996ms: Process A3 completed I/O; added to ready queue [Q A0 A1 A6 A3]
time 94410ms: Process A7 completed a CPU burst; 12 bursts to go [Q A0 A1 A6 A3]
time 94410ms: Process A7 switching out of CPU; blocking on I/O until time 95205ms [Q A0 A1 A6 A3]
time 94416ms: Process A0 started using the CPU for 3388ms burst [Q A1 A6 A3]
time 95205ms: Process A7 completed I/O; added to ready queue [Q A1 A6 A3 A7]
time 97804ms: Process A0 completed a CPU burst; 16 bursts to go [Q A1 A6 A3 A7]
time 97804ms: Process A0 switching out of CPU; blocking on I/O until time 97901ms [Q A1 A6 A3 A7]
time 97810ms: Process A1 started using the CPU for 36ms burst [Q A6 A3 A7]
time 97846ms: Process A1 completed a CPU burst; 18 bursts to go [Q A6 A3 A7]
time 97846ms: Process A1 switching out of CPU; blocking on I/O until time 98486ms [Q A6 A3 A7]
time 97852ms: Process A6 started using the CPU for 58ms burst [Q A3 A7]
time 97901ms: Process A0 completed I/O; added to ready queue [Q A3 A7 A0]
time 97910ms: Process A6 completed a CPU burst; 17 bursts to go [Q A3 A7 A0]
time 97910ms: Process A6 switching out of CPU; blocking on I/O until time 99969ms [Q A3 A7 A0]
time 97916ms: Process A3 started using the CPU for 316ms burst [Q A7 A0]
time 98232ms: Process A3 completed a CPU burst; 3 bursts to go [Q A7 A0]
time 98232ms: Process A3 switching out of CPU; blocking on I/O until time 98903ms [Q A7 A0]
time 98238ms: Process A7 started using the CPU for 33ms burst [Q A0]
time 98271ms: Process A7 completed a CPU burst; 11 bursts to go [Q A0]
time 98271ms: Process A7 switching out of CPU; blocking on I/O until time 100858ms [Q A0]
time 98277ms: Process A0 started using the CPU for 100ms burst [Q empty]
time 98377ms: Process A0 completed a CPU burst; 15 bursts to go [Q empty]
time 98377ms: Process A0 switching out of CPU; blocking on I/O until time 98867ms [Q empty]
time 98486ms: Process A1 completed I/O; added to ready queue [Q A1]
time 98489ms: Process A1 started using the CPU for 4060ms burst [Q empty]
time 98867ms: Process A0 completed I/O; added to ready queue [Q A0]
time 98903ms: Process A3 completed I/O; added to ready queue [Q A0 A3]
time 99969ms: Process A6 completed I/O; added to ready queue [Q A0 A3 A6]
time 100858ms: Process A7 completed I/O; added to ready queue [Q A0 A3 A6 A7]
time 102549ms: Process A1 completed a CPU burst; 17 bursts to go [Q A0 A3 A6 A7]
time 102549ms: Process A1 switching out of CPU; blocking on I/O until time 102642ms [Q A0 A3 A6 A7]
time 102555ms: Process A0 started using the CPU for 3868ms burst [Q A3 A6 A7]
time 102642ms: Process A1 completed I/O; added to ready queue [Q A3 A6 A7 A1]
time 106423ms: Process A0 completed a CPU burst; 14 bursts to go [Q A3 A6 A7 A1]
time 106423ms: Process A0 switching out of CPU; blocking on I/O until time 106538ms [Q A3 A6 A7 A1]
time 106429ms: Process A3 started using the CPU for 204ms burst [Q A6 A7 A1]
time 106538ms: Process A0 completed I/O; added to ready queue [Q A6 A7 A1 A0]
time 106633ms: Process A3 completed a CPU burst; 2 bursts to go [Q A6 A7 A1 A0]
time 106633ms: Process A3 switching out of CPU; blocking on I/O until time 106968ms [Q A6 A7 A1 A0]
time 106639ms: Process A6 started using the CPU for 455ms burst [Q A7 A1 A0]
time 106968ms: Process A3 completed I/O; added to ready queue [Q A7 A1 A0 A3]
time 107094ms: Process A6 completed a CPU burst; 16 bursts to go [Q A7 A1 A0 A3]
time 107094ms: Process A6 switching out of CPU; blocking on I/O until time 110209ms [Q A7 A1 A0 A3]
time 107100ms: Process A7 started using the CPU for 875ms burst [Q A1 A0 A3]
time 107975ms: Process A7 completed a CPU burst; 10 bursts to go [Q A1 A0 A3]
time 107975ms: Process A7 switching out of CPU; blocking on I/O until time 110330ms [Q A1 A0 A3]
time 107981ms: Process A1 started using the CPU for 3904ms burst [Q A0 A3]
time 110209ms: Process A6 completed I/O; added to ready queue [Q A0 A3 A6]
time 110330ms: Process A7 completed I/O; added to ready queue [Q A0 A3 A6 A7]
time 111885ms: Process A1 completed a CPU burst; 16 bursts to go [Q A0 A3 A6 A7]
time 111885ms: Process A1 switching out of CPU; blocking on I/O until time 112422ms [Q A0 A3 A6 A7]
time 111891ms: Process A0 started using the CPU for 1516ms burst [Q A3 A6 A7]
time 112422ms: Process A1 completed I/O; added to ready queue [Q A3 A6 A7 A1]
time 113407ms: Process A0 completed a CPU burst; 13 bursts to go [Q A3 A6 A7 A1]
time 113407ms: Process A0 switching out of CPU; blocking on I/O until time 113721ms [Q A3 A6 A7 A1]
time 113413ms: Process A3 started using the CPU for 2328ms burst [Q A6 A7 A1]
time 113721ms: Process A0 completed I/O; added to ready queue [Q A6 A7 A1 A0]
time 115741ms: Process A3 completed a CPU burst; 1 burst to go [Q A6 A7 A1 A0]
time 115741ms: Process A3 switching out of CPU; blocking on I/O until time 116640ms [Q A6 A7 A1 A0]
time 115747ms: Process A6 started using the CPU for 826ms burst [Q A7 A1 A0]
time 116573ms: Process A6 completed a CPU burst; 15 bursts to go [Q A7 A1 A0]
time 116573ms: Process A6 switching out of CPU; blocking on I/O until time 119216ms [Q A7 A1 A0]
time 116579ms: Process A7 started using the CPU for 53ms burst [Q A1 A0]
time 116632ms: Process A7 completed a CPU burst; 9 bursts to go [Q A1 A0]
time 116632ms: Process A7 switching out of CPU; blocking on I/O until time 116875ms [Q A1 A0]
time 116638ms: Process A1 started using the CPU for 1488ms burst [Q A0]
time 116640ms: Process A3 completed I/O; added to ready queue [Q A0 A3]
time 116875ms: Process A7 completed I/O; added to ready queue [Q A0 A3 A7]
time 118126ms: Process A1 completed a CPU burst; 15 bursts to go [Q A0 A3 A7]
time 118126ms: Process A1 switching out of CPU; blocking on I/O until time 118533ms [Q A0 A3 A7]
time 118132ms: Process A0 started using the CPU for 1260ms burst [Q A3 A7]
time 118533ms: Process A1 completed I/O; added to ready queue [Q A3 A7 A1]
time 119216ms: Process A6 completed I/O; added to ready queue [Q A3 A7 A1 A6]
time 119392ms: Process A0 completed a CPU burst; 12 bursts to go [Q A3 A7 A1 A6]
time 119392ms: Process A0 switching out of CPU; blocking on I/O until time 119808ms [Q A3 A7 A1 A6]
time 119398ms: Process A3 started using the CPU for 2760ms burst [Q A7 A1 A6]
time 119808ms: Process A0 completed I/O; added to ready queue [Q A7 A1 A6 A0]
time 122158ms: Process A3 terminated [Q A7 A1 A6 A0]
time 122164ms: Process A7 started using the CPU for 64ms burst [Q A1 A6 A0]
time 122228ms: Process A7 completed a CPU burst; 8 bursts to go [Q A1 A6 A0]
time 122228ms: Process A7 switching out of CPU; blocking on I/O until time 125727ms [Q A1 A6 A0]
time 122234ms: Process A1 started using the CPU for 1080ms burst [Q A6 A0]
time 123314ms: Process A1 completed a CPU burst; 14 bursts to go [Q A6 A0]
time 123314ms: Process A1 switching out of CPU; blocking on I/O until time 123368ms [Q A6 A0]
time 123320ms: Process A6 started using the CPU for 587ms burst [Q A0]
time 123368ms: Process A1 completed I/O; added to ready queue [Q A0 A1]
time 123907ms: Process A6 completed a CPU burst; 14 bursts to go [Q A0 A1]
time 123907ms: Process A6 switching out of CPU; blocking on I/O until time 125830ms [Q A0 A1]
time 123913ms: Process A0 started using the CPU for 728ms burst [Q A1]
time 124641ms: Process A0 completed a CPU burst; 11 bursts to go [Q A1]
time 124641ms: Process A0 switching out of CPU; blocking on I/O until time 125417ms [Q A1]
time 124647ms: Process A1 started using the CPU for 916ms burst [Q empty]
time 125417ms: Process A0 completed I/O; added to ready queue [Q A0]
time 125563ms: Process A1 completed a CPU burst; 13 bursts to go [Q A0]
time 125563ms: Process A1 switching out of CPU; blocking on I/O until time 125637ms [Q A0]
time 125569ms: Process A0 started using the CPU for 2568ms burst [Q empty]
time 125637ms: Process A1 completed I/O; added to ready queue [Q A1]
time 125727ms: Process A7 completed I/O; added to ready queue [Q A1 A7]
time 125830ms: Process A6 completed I/O; added to ready queue [Q A1 A7 A6]
time 128137ms: Process A0 completed a CPU burst; 10 bursts to go [Q A1 A7 A6]
time 128137ms: Process A0 switching out of CPU; blocking on I/O until time 128488ms [Q A1 A7 A6]
time 128143ms: Process A1 started using the CPU for 3724ms burst [Q A7 A6]
time 128488ms: Process A0 completed I/O; added to ready queue [Q A7 A6 A0]
time 131867ms: Process A1 completed a CPU burst; 12 bursts to go [Q A7 A6 A0]
time 131867ms: Process A1 switching out of CPU; blocking on I/O until time 131981ms [Q A7 A6 A0]
time 131873ms: Process A7 started using the CPU for 264ms burst [Q A6 A0]
time 131981ms: Process A1 completed I/O; added to ready queue [Q A6 A0 A1]
time 132137ms: Process A7 completed a CPU burst; 7 bursts to go [Q A6 A0 A1]
time 132137ms: Process A7 switching out of CPU; blocking on I/O until time 133188ms [Q A6 A0 A1]
time 132143ms: Process A6 started using the CPU for 292ms burst [Q A0 A1]
time 132435ms: Process A6 completed a CPU burst; 13 bursts to go [Q A0 A1]
time 132435ms: Process A6 switching out of CPU; blocking on I/O until time 136918ms [Q A0 A1]
time 132441ms: Process A0 started using the CPU for 1220ms burst [Q A1]
time 133188ms: Process A7 completed I/O; added to ready queue [Q A1 A7]
time 133661ms: Process A0 completed a CPU burst; 9 bursts to go [Q A1 A7]
time 133661ms: Process A0 switching out of CPU; blocking on I/O until time 134547ms [Q A1 A7]
time 133667ms: Process A1 started using the CPU for 1764ms burst [Q A7]
time 134547ms: Process A0 completed I/O; added to ready queue [Q A7 A0]
time 135431ms: Process A1 completed a CPU burst; 11 bursts to go [Q A7 A0]
time 135431ms: Process A1 switching out of CPU; blocking on I/O until time 135716ms [Q A7 A0]
time 135437ms: Process A7 started using the CPU for 228ms burst [Q A0]
time 135665ms: Process A7 completed a CPU burst; 6 bursts to go [Q A0]
time 135665ms: Process A7 switching out of CPU; blocking on I/O until time 137932ms [Q A0]
time 135671ms: Process A0 started using the CPU for 2296ms burst [Q empty]
time 135716ms: Process A1 completed I/O; added to ready queue [Q A1]
time 136918ms: Process A6 completed I/O; added to ready queue [Q A1 A6]
time 137932ms: Process A7 completed I/O; added to ready queue [Q A1 A6 A7]
time 137967ms: Process A0 completed a CPU burst; 8 bursts to go [Q A1 A6 A7]
time 137967ms: Process A0 switching out of CPU; blocking on I/O until time 138634ms [Q A1 A6 A7]
time 137973ms: Process A1 started using the CPU for 860ms burst [Q A6 A7]
time 138634ms: Process A0 completed I/O; added to ready queue [Q A6 A7 A0]
time 138833ms: Process A1 completed a CPU burst; 10 bursts to go [Q A6 A7 A0]
time 138833ms: Process A1 switching out of CPU; blocking on I/O until time 138935ms [Q A6 A7 A0]
time 138839ms: Process A6 started using the CPU for 572ms burst [Q A7 A0]
time 138935ms: Process A1 completed I/O; added to ready queue [Q A7 A0 A1]
time 139411ms: Process A6 completed a CPU burst; 12 bursts to go [Q A7 A0 A1]
time 139411ms: Process A6 switching out of CPU; blocking on I/O until time 139934ms [Q A7 A0 A1]
time 139417ms: Process A7 started using the CPU for 37ms burst [Q A0 A1]
time 139454ms: Process A7 completed a CPU burst; 5 bursts to go [Q A0 A1]
time 139454ms: Process A7 switching out of CPU; blocking on I/O until time 144953ms [Q A0 A1]
time 139460ms: Process A0 started using the CPU for 3268ms burst [Q A1]
time 139934ms: Process A6 completed I/O; added to ready queue [Q A1 A6]
time 142728ms: Process A0 completed a CPU burst; 7 bursts to go [Q A1 A6]
time 142728ms: Process A0 switching out of CPU; blocking on I/O until time 143654ms [Q A1 A6]
time 142734ms: Process A1 started using the CPU for 2700ms burst [Q A6]
time 143654ms: Process A0 completed I/O; added to ready queue [Q A6 A0]
time 144953ms: Process A7 completed I/O; added to ready queue [Q A6 A0 A7]
time 145434ms: Process A1 completed a CPU burst; 9 bursts to go [Q A6 A0 A7]
time 145434ms: Process A1 switching out of CPU; blocking on I/O until time 146204ms [Q A6 A0 A7]
time 145440ms: Process A6 started using the CPU for 494ms burst [Q A0 A7]
time 145934ms: Process A6 completed a CPU burst; 11 bursts to go [Q A0 A7]
time 145934ms: Process A6 switching out of CPU; blocking on I/O until time 153025ms [Q A0 A7]
time 145940ms: Process A0 started using the CPU for 3468ms burst [Q A7]
time 146204ms: Process A1 completed I/O; added to ready queue [Q A7 A1]
time 149408ms: Process A0 completed a CPU burst; 6 bursts to go [Q A7 A1]
time 149408ms: Process A0 switching out of CPU; blocking on I/O until time 149699ms [Q A7 A1]
time 149414ms: Process A7 started using the CPU for 364ms burst [Q A1]
time 149699ms: Process A0 completed I/O; added to ready queue [Q A1 A0]
time 149778ms: Process A7 completed a CPU burst; 4 bursts to go [Q A1 A0]
time 149778ms: Process A7 switching out of CPU; blocking on I/O until time 154093ms [Q A1 A0]
time 149784ms: Process A1 started using the CPU for 100ms burst [Q A0]
time 149884ms: Process A1 completed a CPU burst; 8 bursts to go [Q A0]
time 149884ms: Process A1 switching out of CPU; blocking on I/O until time 150473ms [Q A0]
time 149890ms: Process A0 started using the CPU for 2392ms burst [Q empty]
time 150473ms: Process A1 completed I/O; added to ready queue [Q A1]
time 152282ms: Process A0 completed a CPU burst; 5 bursts to go [Q A1]
time 152282ms: Process A0 switching out of CPU; blocking on I/O until time 152393ms [Q A1]
time 152288ms: Process A1 started using the CPU for 420ms burst [Q empty]
time 152393ms: Process A0 completed I/O; added to ready queue [Q A0]
time 152708ms: Process A1 completed a CPU burst; 7 bursts to go [Q A0]
time 152708ms: Process A1 switching out of CPU; blocking on I/O until time 153420ms [Q A0]
time 152714ms: Process A0 started using the CPU for 1976ms burst [Q empty]
time 153025ms: Process A6 completed I/O; added to ready queue [Q A6]
time 153420ms: Process A1 completed I/O; added to ready queue [Q A6 A1]
time 154093ms: Process A7 completed I/O; added to ready queue [Q A6 A1 A7]
time 154690ms: Process A0 completed a CPU burst; 4 bursts to go [Q A6 A1 A7]
time 154690ms: Process A0 switching out of CPU; blocking on I/O until time 155257ms [Q A6 A1 A7]
time 154696ms: Process A6 started using the CPU for 19ms burst [Q A1 A7]
time 154715ms: Process A6 completed a CPU burst; 10 bursts to go [Q A1 A7]
time 154715ms: Process A6 switching out of CPU; blocking on I/O until time 158934ms [Q A1 A7]
time 154721ms: Process A1 started using the CPU for 3504ms burst [Q A7]
time 155257ms: Process A0 completed I/O; added to ready queue [Q A7 A0]
time 158225ms: Process A1 completed a CPU burst; 6 bursts to go [Q A7 A0]
time 158225ms: Process A1 switching out of CPU; blocking on I/O until time 158899ms [Q A7 A0]
time 158231ms: Process A7 started using the CPU for 278ms burst [Q A0]
time 158509ms: Process A7 completed a CPU burst; 3 bursts to go [Q A0]
time 158509ms: Process A7 switching out of CPU; blocking on I/O until time 161024ms [Q A0]
time 158515ms: Process A0 started using the CPU for 312ms burst [Q empty]
time 158827ms: Process A0 completed a CPU burst; 3 bursts to go [Q empty]
time 158827ms: Process A0 switching out of CPU; blocking on I/O until time 159375ms [Q empty]
time 158899ms: Process A1 completed I/O; added to ready queue [Q A1]
time 158902ms: Process A1 started using the CPU for 3504ms burst [Q empty]
time 158934ms: Process A6 completed I/O; added to ready queue [Q A6]
time 159375ms: Process A0 completed I/O; added to ready queue [Q A6 A0]
time 161024ms: Process A7 completed I/O; added to ready queue [Q A6 A0 A7]
time 162406ms: Process A1 completed a CPU burst; 5 bursts to go [Q A6 A0 A7]
time 162406ms: Process A1 switching out of CPU; blocking on I/O until time 162743ms [Q A6 A0 A7]
time 162412ms: Process A6 started using the CPU for 355ms burst [Q A0 A7]
time 162743ms: Process A1 completed I/O; added to ready queue [Q A0 A7 A1]
time 162767ms: Process A6 completed a CPU burst; 9 bursts to go [Q A0 A7 A1]
time 162767ms: Process A6 switching out of CPU; blocking on I/O until time 165738ms [Q A0 A7 A1]
time 162773ms: Process A0 started using the CPU for 1440ms burst [Q A7 A1]
time 164213ms: Process A0 completed a CPU burst; 2 bursts to go [Q A7 A1]
time 164213ms: Process A0 switching out of CPU; blocking on I/O until time 164352ms [Q A7 A1]
time 164219ms: Process A7 started using the CPU for 23ms burst [Q A1]
time 164242ms: Process A7 completed a CPU burst; 2 bursts to go [Q A1]
time 164242ms: Process A7 switching out of CPU; blocking on I/O until time 172125ms [Q A1]
time 164248ms: Process A1 started using the CPU for 2352ms burst [Q empty]
time 164352ms: Process A0 completed I/O; added to ready queue [Q A0]
time 165738ms: Process A6 completed I/O; added to ready queue [Q A0 A6]
time 166600ms: Process A1 completed a CPU burst; 4 bursts to go [Q A0 A6]
time 166600ms: Process A1 switching out of CPU; blocking on I/O until time 166854ms [Q A0 A6]
time 166606ms: Process A0 started using the CPU for 3052ms burst [Q A6]
time 166854ms: Process A1 completed I/O; added to ready queue [Q A6 A1]
time 169658ms: Process A0 completed a CPU burst; 1 burst to go [Q A6 A1]
time 169658ms: Process A0 switching out of CPU; blocking on I/O until time 170219ms [Q A6 A1]
time 169664ms: Process A6 started using the CPU for 81ms burst [Q A1]
time 169745ms: Process A6 completed a CPU burst; 8 bursts to go [Q A1]
time 169745ms: Process A6 switching out of CPU; blocking on I/O until time 177188ms [Q A1]
time 169751ms: Process A1 started using the CPU for 2652ms burst [Q empty]
time 170219ms: Process A0 completed I/O; added to ready queue [Q A0]
time 172125ms: Process A7 completed I/O; added to ready queue [Q A0 A7]
time 172403ms: Process A1 completed a CPU burst; 3 bursts to go [Q A0 A7]
time 172403ms: Process A1 switching out of CPU; blocking on I/O until time 173174ms [Q A0 A7]
time 172409ms: Process A0 started using the CPU for 2044ms burst [Q A7]
time 173174ms: Process A1 completed I/O; added to ready queue [Q A7 A1]
time 174453ms: Process A0 terminated [Q A7 A1]
time 174459ms: Process A7 started using the CPU for 188ms burst [Q A1]
time 174647ms: Process A7 completed a CPU burst; 1 burst to go [Q A1]
time 174647ms: Process A7 switching out of CPU; blocking on I/O until time 178546ms [Q A1]
time 174653ms: Process A1 started using the CPU for 3812ms burst [Q empty]
time 177188ms: Process A6 completed I/O; added to ready queue [Q A6]
time 178465ms: Process A1 completed a CPU burst; 2 bursts to go [Q A6]
time 178465ms: Process A1 switching out of CPU; blocking on I/O until time 178995ms [Q A6]
time 178471ms: Process A6 started using the CPU for 25ms burst [Q empty]
time 178496ms: Process A6 completed a CPU burst; 7 bursts to go [Q empty]
time 178496ms: Process A6 switching out of CPU; blocking on I/O until time 179443ms [Q empty]
time 178546ms: Process A7 completed I/O; added to ready queue [Q A7]
time 178549ms: Process A7 started using the CPU for 214ms burst [Q empty]
time 178763ms: Process A7 terminated [Q empty]
time 178995ms: Process A1 completed I/O; added to ready queue [Q A1]
time 178998ms: Process A1 started using the CPU for 2288ms burst [Q empty]
time 179443ms: Process A6 completed I/O; added to ready queue [Q A6]
time 181286ms: Process A1 completed a CPU burst; 1 burst to go [Q A6]
time 181286ms: Process A1 switching out of CPU; blocking on I/O until time 181455ms [Q A6]
time 181292ms: Process A6 started using the CPU for 445ms burst [Q empty]
time 181455ms: Process A1 completed I/O; added to ready queue [Q A1]
time 181737ms: Process A6 completed a CPU burst; 6 bursts to go [Q A1]
time 181737ms: Process A6 switching out of CPU; blocking on I/O until time 184948ms [Q A1]
time 181743ms: Process A1 started using the CPU for 388ms burst [Q empty]
time 182131ms: Process A1 terminated [Q empty]
time 184948ms: Process A6 completed I/O; added to ready queue [Q A6]
time 184951ms: Process A6 started using the CPU for 35ms burst [Q empty]
time 184986ms: Process A6 completed a CPU burst; 5 bursts to go [Q empty]
time 184986ms: Process A6 switching out of CPU; blocking on I/O until time 188029ms [Q empty]
time 188029ms: Process A6 completed I/O; added to ready queue [Q A6]
time 188032ms: Process A6 started using the CPU for 245ms burst [Q empty]
time 188277ms: Process A6 completed a CPU burst; 4 bursts to go [Q empty]
time 188277ms: Process A6 switching out of CPU; blocking on I/O until time 195520ms [Q empty]
time 195520ms: Process A6 completed I/O; added to ready queue [Q A6]
time 195523ms: Process A6 started using the CPU for 732ms burst [Q empty]
time 196255ms: Process A6 completed a CPU burst; 3 bursts to go [Q empty]
time 196255ms: Process A6 switching out of CPU; blocking on I/O until time 198322ms [Q empty]
time 198322ms: Process A6 completed I/O; added to ready queue [Q A6]
time 198325ms: Process A6 started using the CPU for 850ms burst [Q empty]
time 199175ms: Process A6 completed a CPU burst; 2 bursts to go [Q empty]
time 199175ms: Process A6 switching out of CPU; blocking on I/O until time 205978ms [Q empty]
time 205978ms: Process A6 completed I/O; added to ready queue [Q A6]
time 205981ms: Process A6 started using the CPU for 667ms burst [Q empty]
time 206648ms: Process A6 completed a CPU burst; 1 burst to go [Q empty]
time 206648ms: Process A6 switching out of CPU; blocking on I/O until time 206899ms [Q empty]
time 206899ms: Process A6 completed I/O; added to ready queue [Q A6]
time 206902ms: Process A6 started using the CPU for 370ms burst [Q empty]
time 207272ms: Process A6 terminated [Q empty]
time 207275ms: Simulator ended for FCFS [Q empty]

time 0ms: Simulator started for SJF [Q empty]
time 54ms: Process A0 (tau 1000ms) arrived; added to ready queue [Q A0]
time 56ms: Process A1 (tau 1000ms) arrived; added to ready queue [Q A1]
time 57ms: Process A0 (tau 1000ms) started using the CPU for 3764ms burst [Q A1]
time 115ms: Process A5 (tau 1000ms) arrived; added to ready queue [Q A1 A5]
time 242ms: Process A6 (tau 1000ms) arrived; added to ready queue [Q A1 A5 A6]
time 346ms: Process A4 (tau 1000ms) arrived; added to ready queue [Q A1 A4 A5 A6]
time 357ms: Process A7 (tau 1000ms) arrived; added to ready queue [Q A1 A4 A5 A6 A7]
time 456ms: Process A2 (tau 1000ms) arrived; added to ready queue [Q A1 A2 A4 A5 A6 A7]
time 758ms: Process A3 (tau 1000ms) arrived; added to ready queue [Q A1 A2 A3 A4 A5 A6 A7]
time 3821ms: Process A0 (tau 1000ms) completed a CPU burst; 28 bursts to go [Q A1 A2 A3 A4 A5 A6 A7]
time 3821ms: Recalculated tau for process A0: old tau 1000ms ==> new tau 3626ms [Q A1 A2 A3 A4 A5 A6 A7]
time 3821ms: Process A0 switching out of CPU; blocking on I/O until time 4510ms [Q A1 A2 A3 A4 A5 A6 A7]
time 3827ms: Process A1 (tau 1000ms) started using the CPU for 2828ms burst [Q A2 A3 A4 A5 A6 A7]
time 4510ms: Process A0 (tau 3626ms) completed I/O; added to ready queue [Q A2 A3 A4 A5 A6 A7 A0]
time 6655ms: Process A1 (tau 1000ms) completed a CPU burst; 30 bursts to go [Q A2 A3 A4 A5 A6 A7 A0]
time 6655ms: Recalculated tau for process A1: old tau 1000ms ==> new tau 2737ms [Q A2 A3 A4 A5 A6 A7 A0]
time 6655ms: Process A1 switching out of CPU; blocking on I/O until time 6980ms [Q A2 A3 A4 A5 A6 A7 A0]
time 6661ms: Process A2 (tau 1000ms) started using the CPU for 1896ms burst [Q A3 A4 A5 A6 A7 A0]
time 6980ms: Process A1 (tau 2737ms) completed I/O; added to ready queue [Q A3 A4 A5 A6 A7 A1 A0]
time 8557ms: Process A2 (tau 1000ms) completed a CPU burst; 8 bursts to go [Q A3 A4 A5 A6 A7 A1 A0]
time 8557ms: Recalculated tau for process A2: old tau 1000ms ==> new tau 1852ms [Q A3 A4 A5 A6 A7 A1 A0]
time 8557ms: Process A2 switching out of CPU; blocking on I/O until time 9178ms [Q A3 A4 A5 A6 A7 A1 A0]
time 8563ms: Process A3 (tau 1000ms) started using the CPU for 548ms burst [Q A4 A5 A6 A7 A1 A0]
time 9111ms: Process A3 (tau 1000ms) completed a CPU burst; 15 bursts to go [Q A4 A5 A6 A7 A1 A0]
time 9111ms: Recalculated tau for process A3: old tau 1000ms ==> new tau 571ms [Q A4 A5 A6 A7 A1 A0]
time 9111ms: Process A3 switching out of CPU; blocking on I/O until time 9913ms [Q A4 A5 A6 A7 A1 A0]
time 9117ms: Process A4 (tau 1000ms) started using the CPU for 2428ms burst [Q A5 A6 A7 A1 A0]
time 9178ms: Process A2 (tau 1852ms) completed I/O; added to ready queue [Q A5 A6 A7 A2 A1 A0]
time 9913ms: Process A3 (tau 571ms) completed I/O; added to ready queue [Q A3 A5 A6 A7 A2 A1 A0]
time 11545ms: Process A4 (tau 1000ms) completed a CPU burst; 1 burst to go [Q A3 A5 A6 A7 A2 A1 A0]
time 11545ms: Recalculated tau for process A4: old tau 1000ms ==> new tau 2357ms [Q A3 A5 A6 A7 A2 A1 A0]
time 11545ms: Process A4 switching out of CPU; blocking on I/O until time 12057ms [Q A3 A5 A6 A7 A2 A1 A0]
time 11551ms: Process A3 (tau 571ms) started using the CPU for 428ms burst [Q A5 A6 A7 A2 A1 A0]
time 11979ms: Process A3 (tau 571ms) completed a CPU burst; 14 bursts to go [Q A5 A6 A7 A2 A1 A0]
time 11979ms: Recalculated tau for process A3: old tau 571ms ==> new tau 436ms [Q A5 A6 A7 A2 A1 A0]
time 11979ms: Process A3 switching out of CPU; blocking on I/O until time 12920ms [Q A5 A6 A7 A2 A1 A0]
time 11985ms: Process A5 (tau 1000ms) started using the CPU for 564ms burst [Q A6 A7 A2 A1 A0]
time 12057ms: Process A4 (tau 2357ms) completed I/O; added to ready queue [Q A6 A7 A2 A4 A1 A0]
time 12549ms: Process A5 terminated [Q A6 A7 A2 A4 A1 A0]
time 12555ms: Process A6 (tau 1000ms) started using the CPU for 761ms burst [Q A7 A2 A4 A1 A0]
time 12920ms: Process A3 (tau 436ms) completed I/O; added to ready queue [Q A3 A7 A2 A4 A1 A0]
time 13316ms: Process A6 (tau 1000ms) completed a CPU burst; 26 bursts to go [Q A3 A7 A2 A4 A1 A0]
time 13316ms: Recalculated tau for process A6: old tau 1000ms ==> new tau 773ms [Q A3 A7 A2 A4 A1 A0]
time 13316ms: Process A6 switching out of CPU; blocking on I/O until time 15583ms [Q A3 A7 A2 A4 A1 A0]
time 13322ms: Process A3 (tau 436ms) started using the CPU for 1432ms burst [Q A7 A2 A4 A1 A0]
time 14754ms: Process A3 (tau 436ms) completed a CPU burst; 13 bursts to go [Q A7 A2 A4 A1 A0]
time 14754ms: Recalculated tau for process A3: old tau 436ms ==> new tau 1383ms [Q A7 A2 A4 A1 A0]
time 14754ms: Process A3 switching out of CPU; blocking on I/O until time 15074ms [Q A7 A2 A4 A1 A0]
time 14760ms: Process A7 (tau 1000ms) started using the CPU for 297ms burst [Q A2 A4 A1 A0]
time 15057ms: Process A7 (tau 1000ms) completed a CPU burst; 20 bursts to go [Q A2 A4 A1 A0]
time 15057ms: Recalculated tau for process A7: old tau 1000ms ==> new tau 333ms [Q A2 A4 A1 A0]
time 15057ms: Process A7 switching out of CPU; blocking on I/O until time 22924ms [Q A2 A4 A1 A0]
time 15063ms: Process A2 (tau 1852ms) started using the CPU for 2940ms burst [Q A4 A1 A0]
time 15074ms: Process A3 (tau 1383ms) completed I/O; added to ready queue [Q A3 A4 A1 A0]
time 15583ms: Process A6 (tau 773ms) completed I/O; added to ready queue [Q A6 A3 A4 A1 A0]
time 18003ms: Process A2 (tau 1852ms) completed a CPU burst; 7 bursts to go [Q A6 A3 A4 A1 A0]
time 18003ms: Recalculated tau for process A2: old tau 1852ms ==> new tau 2886ms [Q A6 A3 A4 A1 A0]
time 18003ms: Process A2 switching out of CPU; blocking on I/O until time 18445ms [Q A6 A3 A4 A1 A0]
time 18009ms: Process A6 (tau 773ms) started using the CPU for 903ms burst [Q A3 A4 A1 A0]
time 18445ms: Process A2 (tau 2886ms) completed I/O; added to ready queue [Q A3 A4 A1 A2 A0]
time 18912ms: Process A6 (tau 773ms) completed a CPU burst; 25 bursts to go [Q A3 A4 A1 A2 A0]
time 18912ms: Recalculated tau for process A6: old tau 773ms ==> new tau 897ms [Q A3 A4 A1 A2 A0]
time 18912ms: Process A6 switching out of CPU; blocking on I/O until time 20963ms [Q A3 A4 A1 A2 A0]
time 18918ms: Process A3 (tau 1383ms) started using the CPU for 3896ms burst [Q A4 A1 A2 A0]
time 20963ms: Process A6 (tau 897ms) completed I/O; added to ready queue [Q A6 A4 A1 A2 A0]
time 22814ms: Process A3 (tau 1383ms) completed a CPU burst; 12 bursts to go [Q A6 A4 A1 A2 A0]
time 22814ms: Recalculated tau for process A3: old tau 1383ms ==> new tau 3771ms [Q A6 A4 A1 A2 A0]
time 22814ms: Process A3 switching out of CPU; blocking on I/O until time 22941ms [Q A6 A4 A1 A2 A0]
time 22820ms: Process A6 (tau 897ms) started using the CPU for 303ms burst [Q A4 A1 A2 A0]
time 22924ms: Process A7 (tau 333ms) completed I/O; added to ready queue [Q A7 A4 A1 A2 A0]
time 22941ms: Process A3 (tau 3771ms) completed I/O; added to ready queue [Q A7 A4 A1 A2 A0 A3]
time 23123ms: Process A6 (tau 897ms) completed a CPU burst; 24 bursts to go [Q A7 A4 A1 A2 A0 A3]
time 23123ms: Recalculated tau for process A6: old tau 897ms ==> new tau 333ms [Q A7 A4 A1 A2 A0 A3]
time 23123ms: Process A6 switching out of CPU; blocking on I/O until time 30454ms [Q A7 A4 A1 A2 A0 A3]
time 23129ms: Process A7 (tau 333ms) started using the CPU for 598ms burst [Q A4 A1 A2 A0 A3]
time 23727ms: Process A7 (tau 333ms) completed a CPU burst; 19 bursts to go [Q A4 A1 A2 A0 A3]
time 23727ms: Recalculated tau for process A7: old tau 333ms ==> new tau 585ms [Q A4 A1 A2 A0 A3]
time 23727ms: Process A7 switching out of CPU; blocking on I/O until time 26186ms [Q A4 A1 A2 A0 A3]
time 23733ms: Process A4 (tau 2357ms) started using the CPU for 2532ms burst [Q A1 A2 A0 A3]
time 26186ms: Process A7 (tau 585ms) completed I/O; added to ready queue [Q A7 A1 A2 A0 A3]
time 26265ms: Process A4 terminated [Q A7 A1 A2 A0 A3]
time 26271ms: Process A7 (tau 585ms) started using the CPU for 721ms burst [Q A1 A2 A0 A3]
time 26992ms: Process A7 (tau 585ms) completed a CPU burst; 18 bursts to go [Q A1 A2 A0 A3]
time 26992ms: Recalculated tau for process A7: old tau 585ms ==> new tau 715ms [Q A1 A2 A0 A3]
time 26992ms: Process A7 switching out of CPU; blocking on I/O until time 29731ms [Q A1 A2 A0 A3]
time 26998ms: Process A1 (tau 2737ms) started using the CPU for 1444ms burst [Q A2 A0 A3]
time 28442ms: Process A1 (tau 2737ms) completed a CPU burst; 29 bursts to go [Q A2 A0 A3]
time 28442ms: Recalculated tau for process A1: old tau 2737ms ==> new tau 1509ms [Q A2 A0 A3]
time 28442ms: Process A1 switching out of CPU; blocking on I/O until time 28612ms [Q A2 A0 A3]
time 28448ms: Process A2 (tau 2886ms) started using the CPU for 248ms burst [Q A0 A3]
time 28612ms: Process A1 (tau 1509ms) completed I/O; added to ready queue [Q A1 A0 A3]
time 28696ms: Process A2 (tau 2886ms) completed a CPU burst; 6 bursts to go [Q A1 A0 A3]
time 28696ms: Recalculated tau for process A2: old tau 2886ms ==> new tau 380ms [Q A1 A0 A3]
time 28696ms: Process A2 switching out of CPU; blocking on I/O until time 29163ms [Q A1 A0 A3]
time 28702ms: Process A1 (tau 1509ms) started using the CPU for 2476ms burst [Q A0 A3]
time 29163ms: Process A2 (tau 380ms) completed I/O; added to ready queue [Q A2 A0 A3]
time 29731ms: Process A7 (tau 715ms) completed I/O; added to ready queue [Q A2 A7 A0 A3]
time 30454ms: Process A6 (tau 333ms) completed I/O; added to ready queue [Q A6 A2 A7 A0 A3]
time 31178ms: Process A1 (tau 1509ms) completed a CPU burst; 28 bursts to go [Q A6 A2 A7 A0 A3]
time 31178ms: Recalculated tau for process A1: old tau 1509ms ==> new tau 2428ms [Q A6 A2 A7 A0 A3]
time 31178ms: Process A1 switching out of CPU; blocking on I/O until time 31598ms [Q A6 A2 A7 A0 A3]
time 31184ms: Process A6 (tau 333ms) started using the CPU for 194ms burst [Q A2 A7 A0 A3]
time 31378ms: Process A6 (tau 333ms) completed a CPU burst; 23 bursts to go [Q A2 A7 A0 A3]
time 31378ms: Recalculated tau for process A6: old tau 333ms ==> new tau 201ms [Q A2 A7 A0 A3]
time 31378ms: Process A6 switching out of CPU; blocking on I/O until time 38277ms [Q A2 A7 A0 A3]
time 31384ms: Process A2 (tau 380ms) started using the CPU for 952ms burst [Q A7 A0 A3]
time 31598ms: Process A1 (tau 2428ms) completed I/O; added to ready queue [Q A7 A1 A0 A3]
time 32336ms: Process A2 (tau 380ms) completed a CPU burst; 5 bursts to go [Q A7 A1 A0 A3]
time 32336ms: Recalculated tau for process A2: old tau 380ms ==> new tau 924ms [Q A7 A1 A0 A3]
time 32336ms: Process A2 switching out of CPU; blocking on I/O until time 33113ms [Q A7 A1 A0 A3]
time 32342ms: Process A7 (tau 715ms) started using the CPU for 641ms burst [Q A1 A0 A3]
time 32983ms: Process A7 (tau 715ms) completed a CPU burst; 17 bursts to go [Q A1 A0 A3]
time 32983ms: Recalculated tau for process A7: old tau 715ms ==> new tau 645ms [Q A1 A0 A3]
time 32983ms: Process A7 switching out of CPU; blocking on I/O until time 34930ms [Q A1 A0 A3]
time 32989ms: Process A1 (tau 2428ms) started using the CPU for 2256ms burst [Q A0 A3]
time 33113ms: Process A2 (tau 924ms) completed I/O; added to ready queue [Q A2 A0 A3]
time 34930ms: Process A7 (tau 645ms) completed I/O; added to ready queue [Q A7 A2 A0 A3]
time 35245ms: Process A1 (tau 2428ms) completed a CPU burst; 27 bursts to go [Q A7 A2 A0 A3]
time 35245ms: Recalculated tau for process A1: old tau 2428ms ==> new tau 2265ms [Q A7 A2 A0 A3]
time 35245ms: Process A1 switching out of CPU; blocking on I/O until time 35538ms [Q A7 A2 A0 A3]
time 35251ms: Process A7 (tau 645ms) started using the CPU for 128ms burst [Q A2 A0 A3]
time 35379ms: Process A7 (tau 645ms) completed a CPU burst; 16 bursts to go [Q A2 A0 A3]
time 35379ms: Recalculated tau for process A7: old tau 645ms ==> new tau 154ms [Q A2 A0 A3]
time 35379ms: Process A7 switching out of CPU; blocking on I/O until time 41550ms [Q A2 A0 A3]
time 35385ms: Process A2 (tau 924ms) started using the CPU for 1796ms burst [Q A0 A3]
time 35538ms: Process A1 (tau 2265ms) completed I/O; added to ready queue [Q A1 A0 A3]
time 37181ms: Process A2 (tau 924ms) completed a CPU burst; 4 bursts to go [Q A1 A0 A3]
time 37181ms: Recalculated tau for process A2: old tau 924ms ==> new tau 1753ms [Q A1 A0 A3]
time 37181ms: Process A2 switching out of CPU; blocking on I/O until time 37595ms [Q A1 A0 A3]
time 37187ms: Process A1 (tau 2265ms) started using the CPU for 1188ms burst [Q A0 A3]
time 37595ms: Process A2 (tau 1753ms) completed I/O; added to ready queue [Q A2 A0 A3]
time 38277ms: Process A6 (tau 201ms) completed I/O; added to ready queue [Q A6 A2 A0 A3]
time 38375ms: Process A1 (tau 2265ms) completed a CPU burst; 26 bursts to go [Q A6 A2 A0 A3]
time 38375ms: Recalculated tau for process A1: old tau 2265ms ==> new tau 1242ms [Q A6 A2 A0 A3]
time 38375ms: Process A1 switching out of CPU; blocking on I/O until time 39155ms [Q A6 A2 A0 A3]
time 38381ms: Process A6 (tau 201ms) started using the CPU for 203ms burst [Q A2 A0 A3]
time 38584ms: Process A6 (tau 201ms) completed a CPU burst; 22 bursts to go [Q A2 A0 A3]
time 38584ms: Recalculated tau for process A6: old tau 201ms ==> new tau 203ms [Q A2 A0 A3]
time 38584ms: Process A6 switching out of CPU; blocking on I/O until time 41387ms [Q A2 A0 A3]
time 38590ms: Process A2 (tau 1753ms) started using the CPU for 2200ms burst [Q A0 A3]
time 39155ms: Process A1 (tau 1242ms) completed I/O; added to ready queue [Q A1 A0 A3]
time 40790ms: Process A2 (tau 1753ms) completed a CPU burst; 3 bursts to go [Q A1 A0 A3]
time 40790ms: Recalculated tau for process A2: old tau 1753ms ==> new tau 2178ms [Q A1 A0 A3]
time 40790ms: Process A2 switching out of CPU; blocking on I/O until time 40808ms [Q A1 A0 A3]
time 40796ms: Process A1 (tau 1242ms) started using the CPU for 2812ms burst [Q A0 A3]
time 40808ms: Process A2 (tau 2178ms) completed I/O; added to ready queue [Q A2 A0 A3]
time 41387ms: Process A6 (tau 203ms) completed I/O; added to ready queue [Q A6 A2 A0 A3]
time 41550ms: Process A7 (tau 154ms) completed I/O; added to ready queue [Q A7 A6 A2 A0 A3]
time 43608ms: Process A1 (tau 1242ms) completed a CPU burst; 25 bursts to go [Q A7 A6 A2 A0 A3]
time 43608ms: Recalculated tau for process A1: old tau 1242ms ==> new tau 2734ms [Q A7 A6 A2 A0 A3]
time 43608ms: Process A1 switching out of CPU; blocking on I/O until time 44474ms [Q A7 A6 A2 A0 A3]
time 43614ms: Process A7 (tau 154ms) started using the CPU for 277ms burst [Q A6 A2 A0 A3]
time 43891ms: Process A7 (tau 154ms) completed a CPU burst; 15 bursts to go [Q A6 A2 A0 A3]
time 43891ms: Recalculated tau for process A7: old tau 154ms ==> new tau 271ms [Q A6 A2 A0 A3]
time 43891ms: Process A7 switching out of CPU; blocking on I/O until time 44742ms [Q A6 A2 A0 A3]
time 43897ms: Process A6 (tau 203ms) started using the CPU for 603ms burst [Q A2 A0 A3]
time 44474ms: Process A1 (tau 2734ms) completed I/O; added to ready queue [Q A2 A1 A0 A3]
time 44500ms: Process A6 (tau 203ms) completed a CPU burst; 21 bursts to go [Q A2 A1 A0 A3]
time 44500ms: Recalculated tau for process A6: old tau 203ms ==> new tau 583ms [Q A2 A1 A0 A3]
time 44500ms: Process A6 switching out of CPU; blocking on I/O until time 47567ms [Q A2 A1 A0 A3]
time 44506ms: Process A2 (tau 2178ms) started using the CPU for 1512ms burst [Q A1 A0 A3]
time 44742ms: Process A7 (tau 271ms) completed I/O; added to ready queue [Q A7 A1 A0 A3]
time 46018ms: Process A2 (tau 2178ms) completed a CPU burst; 2 bursts to go [Q A7 A1 A0 A3]
time 46018ms: Recalculated tau for process A2: old tau 2178ms ==> new tau 1546ms [Q A7 A1 A0 A3]
time 46018ms: Process A2 switching out of CPU; blocking on I/O until time 46808ms [Q A7 A1 A0 A3]
time 46024ms: Process A7 (tau 271ms) started using the CPU for 984ms burst [Q A1 A0 A3]
time 46808ms: Process A2 (tau 1546ms) completed I/O; added to ready queue [Q A2 A1 A0 A3]
time 47008ms: Process A7 (tau 271ms) completed a CPU burst; 14 bursts to go [Q A2 A1 A0 A3]
time 47008ms: Recalculated tau for process A7: old tau 271ms ==> new tau 949ms [Q A2 A1 A0 A3]
time 47008ms: Process A7 switching out of CPU; blocking on I/O until time 52219ms [Q A2 A1 A0 A3]
time 47014ms: Process A2 (tau 1546ms) started using the CPU for 1764ms burst [Q A1 A0 A3]
time 47567ms: Process A6 (tau 583ms) completed I/O; added to ready queue [Q A6 A1 A0 A3]
time 48778ms: Process A2 (tau 1546ms) completed a CPU burst; 1 burst to go [Q A6 A1 A0 A3]
time 48778ms: Recalculated tau for process A2: old tau 1546ms ==> new tau 1754ms [Q A6 A1 A0 A3]
time 48778ms: Process A2 switching out of CPU; blocking on I/O until time 48865ms [Q A6 A1 A0 A3]
time 48784ms: Process A6 (tau 583ms) started using the CPU for 95ms burst [Q A1 A0 A3]
time 48865ms: Process A2 (tau 1754ms) completed I/O; added to ready queue [Q A2 A1 A0 A3]
time 48879ms: Process A6 (tau 583ms) completed a CPU burst; 20 bursts to go [Q A2 A1 A0 A3]
time 48879ms: Recalculated tau for process A6: old tau 583ms ==> new tau 120ms [Q A2 A1 A0 A3]
time 48879ms: Process A6 switching out of CPU; blocking on I/O until time 49938ms [Q A2 A1 A0 A3]
time 48885ms: Process A2 (tau 1754ms) started using the CPU for 1768ms burst [Q A1 A0 A3]
time 49938ms: Process A6 (tau 120ms) completed I/O; added to ready queue [Q A6 A1 A0 A3]
time 50653ms: Process A2 terminated [Q A6 A1 A0 A3]
time 50659ms: Process A6 (tau 120ms) started using the CPU for 556ms burst [Q A1 A0 A3]
time 51215ms: Process A6 (tau 120ms) completed a CPU burst; 19 bursts to go [Q A1 A0 A3]
time 51215ms: Recalculated tau for process A6: old tau 120ms ==> new tau 535ms [Q A1 A0 A3]
time 51215ms: Process A6 switching out of CPU; blocking on I/O until time 54594ms [Q A1 A0 A3]
time 51221ms: Process A1 (tau 2734ms) started using the CPU for 368ms burst [Q A0 A3]
time 51589ms: Process A1 (tau 2734ms) completed a CPU burst; 24 bursts to go [Q A0 A3]
time 51589ms: Recalculated tau for process A1: old tau 2734ms ==> new tau 487ms [Q A0 A3]
time 51589ms: Process A1 switching out of CPU; blocking on I/O until time 51765ms [Q A0 A3]
time 51595ms: Process A0 (tau 3626ms) started using the CPU for 1732ms burst [Q A3]
time 51765ms: Process A1 (tau 487ms) completed I/O; added to ready queue [Q A1 A3]
time 52219ms: Process A7 (tau 949ms) completed I/O; added to ready queue [Q A1 A7 A3]
time 53327ms: Process A0 (tau 3626ms) completed a CPU burst; 27 bursts to go [Q A1 A7 A3]
time 53327ms: Recalculated tau for process A0: old tau 3626ms ==> new tau 1827ms [Q A1 A7 A3]
time 53327ms: Process A0 switching out of CPU; blocking on I/O until time 53542ms [Q A1 A7 A3]
time 53333ms: Process A1 (tau 487ms) started using the CPU for 200ms burst [Q A7 A3]
time 53533ms: Process A1 (tau 487ms) completed a CPU burst; 23 bursts to go [Q A7 A3]
time 53533ms: Recalculated tau for process A1: old tau 487ms ==> new tau 215ms [Q A7 A3]
time 53533ms: Process A1 switching out of CPU; blocking on I/O until time 54143ms [Q A7 A3]
time 53539ms: Process A7 (tau 949ms) started using the CPU for 961ms burst [Q A3]
time 53542ms: Process A0 (tau 1827ms) completed I/O; added to ready queue [Q A0 A3]
time 54143ms: Process A1 (tau 215ms) completed I/O; added to ready queue [Q A1 A0 A3]
time 54500ms: Process A7 (tau 949ms) completed a CPU burst; 13 bursts to go [Q A1 A0 A3]
time 54500ms: Recalculated tau for process A7: old tau 949ms ==> new tau 961ms [Q A1 A0 A3]
time 54500ms: Process A7 switching out of CPU; blocking on I/O until time 57935ms [Q A1 A0 A3]
time 54506ms: Process A1 (tau 215ms) started using the CPU for 1044ms burst [Q A0 A3]
time 54594ms: Process A6 (tau 535ms) completed I/O; added to ready queue [Q A6 A0 A3]
time 55550ms: Process A1 (tau 215ms) completed a CPU burst; 22 bursts to go [Q A6 A0 A3]
time 55550ms: Recalculated tau for process A1: old tau 215ms ==> new tau 1003ms [Q A6 A0 A3]
time 55550ms: Process A1 switching out of CPU; blocking on I/O until time 56145ms [Q A6 A0 A3]
time 55556ms: Process A6 (tau 535ms) started using the CPU for 599ms burst [Q A0 A3]
time 56145ms: Process A1 (tau 1003ms) completed I/O; added to ready queue [Q A1 A0 A3]
time 56155ms: Process A6 (tau 535ms) completed a CPU burst; 18 bursts to go [Q A1 A0 A3]
time 56155ms: Recalculated tau for process A6: old tau 535ms ==> new tau 596ms [Q A1 A0 A3]
time 56155ms: Process A6 switching out of CPU; blocking on I/O until time 56718ms [Q A1 A0 A3]
time 56161ms: Process A1 (tau 1003ms) started using the CPU for 940ms burst [Q A0 A3]
time 56718ms: Process A6 (tau 596ms) completed I/O; added to ready queue [Q A6 A0 A3]
time 57101ms: Process A1 (tau 1003ms) completed a CPU burst; 21 bursts to go [Q A6 A0 A3]
time 57101ms: Recalculated tau for process A1: old tau 1003ms ==> new tau 944ms [Q A6 A0 A3]
time 57101ms: Process A1 switching out of CPU; blocking on I/O until time 57549ms [Q A6 A0 A3]
time 57107ms: Process A6 (tau 596ms) started using the CPU for 58ms burst [Q A0 A3]
time 57165ms: Process A6 (tau 596ms) completed a CPU burst; 17 bursts to go [Q A0 A3]
time 57165ms: Recalculated tau for process A6: old tau 596ms ==> new tau 85ms [Q A0 A3]
time 57165ms: Process A6 switching out of CPU; blocking on I/O until time 59224ms [Q A0 A3]
time 57171ms: Process A0 (tau 1827ms) started using the CPU for 844ms burst [Q A3]
time 57549ms: Process A1 (tau 944ms) completed I/O; added to ready queue [Q A1 A3]
time 57935ms: Process A7 (tau 961ms) completed I/O; added to ready queue [Q A1 A7 A3]
time 58015ms: Process A0 (tau 1827ms) completed a CPU burst; 26 bursts to go [Q A1 A7 A3]
time 58015ms: Recalculated tau for process A0: old tau 1827ms ==> new tau 894ms [Q A1 A7 A3]
time 58015ms: Process A0 switching out of CPU; blocking on I/O until time 58511ms [Q A1 A7 A3]
time 58021ms: Process A1 (tau 944ms) started using the CPU for 660ms burst [Q A7 A3]
time 58511ms: Process A0 (tau 894ms) completed I/O; added to ready queue [Q A0 A7 A3]
time 58681ms: Process A1 (tau 944ms) completed a CPU burst; 20 bursts to go [Q A0 A7 A3]
time 58681ms: Recalculated tau for process A1: old tau 944ms ==> new tau 675ms [Q A0 A7 A3]
time 58681ms: Process A1 switching out of CPU; blocking on I/O until time 58712ms [Q A0 A7 A3]
time 58687ms: Process A0 (tau 894ms) started using the CPU for 168ms burst [Q A7 A3]
time 58712ms: Process A1 (tau 675ms) completed I/O; added to ready queue [Q A1 A7 A3]
time 58855ms: Process A0 (tau 894ms) completed a CPU burst; 25 bursts to go [Q A1 A7 A3]
time 58855ms: Recalculated tau for process A0: old tau 894ms ==> new tau 205ms [Q A1 A7 A3]
time 58855ms: Process A0 switching out of CPU; blocking on I/O until time 59230ms [Q A1 A7 A3]
time 58861ms: Process A1 (tau 675ms) started using the CPU for 2196ms burst [Q A7 A3]
time 59224ms: Process A6 (tau 85ms) completed I/O; added to ready queue [Q A6 A7 A3]
time 59230ms: Process A0 (tau 205ms) completed I/O; added to ready queue [Q A6 A0 A7 A3]
time 61057ms: Process A1 (tau 675ms) completed a CPU burst; 19 bursts to go [Q A6 A0 A7 A3]
time 61057ms: Recalculated tau for process A1: old tau 675ms ==> new tau 2120ms [Q A6 A0 A7 A3]
time 61057ms: Process A1 switching out of CPU; blocking on I/O until time 62036ms [Q A6 A0 A7 A3]
time 61063ms: Process A6 (tau 85ms) started using the CPU for 455ms burst [Q A0 A7 A3]
time 61518ms: Process A6 (tau 85ms) completed a CPU burst; 16 bursts to go [Q A0 A7 A3]
time 61518ms: Recalculated tau for process A6: old tau 85ms ==> new tau 437ms [Q A0 A7 A3]
time 61518ms: Process A6 switching out of CPU; blocking on I/O until time 64633ms [Q A0 A7 A3]
time 61524ms: Process A0 (tau 205ms) started using the CPU for 736ms burst [Q A7 A3]
time 62036ms: Process A1 (tau 2120ms) completed I/O; added to ready queue [Q A7 A1 A3]
time 62260ms: Process A0 (tau 205ms) completed a CPU burst; 24 bursts to go [Q A7 A1 A3]
time 62260ms: Recalculated tau for process A0: old tau 205ms ==> new tau 710ms [Q A7 A1 A3]
time 62260ms: Process A0 switching out of CPU; blocking on I/O until time 62404ms [Q A7 A1 A3]
time 62266ms: Process A7 (tau 961ms) started using the CPU for 587ms burst [Q A1 A3]
time 62404ms: Process A0 (tau 710ms) completed I/O; added to ready queue [Q A0 A1 A3]
time 62853ms: Process A7 (tau 961ms) completed a CPU burst; 12 bursts to go [Q A0 A1 A3]
time 62853ms: Recalculated tau for process A7: old tau 961ms ==> new tau 606ms [Q A0 A1 A3]
time 62853ms: Process A7 switching out of CPU; blocking on I/O until time 63648ms [Q A0 A1 A3]
time 62859ms: Process A0 (tau 710ms) started using the CPU for 1372ms burst [Q A1 A3]
time 63648ms: Process A7 (tau 606ms) completed I/O; added to ready queue [Q A7 A1 A3]
time 64231ms: Process A0 (tau 710ms) completed a CPU burst; 23 bursts to go [Q A7 A1 A3]
time 64231ms: Recalculated tau for process A0: old tau 710ms ==> new tau 1339ms [Q A7 A1 A3]
time 64231ms: Process A0 switching out of CPU; blocking on I/O until time 64788ms [Q A7 A1 A3]
time 64237ms: Process A7 (tau 606ms) started using the CPU for 33ms burst [Q A1 A3]
time 64270ms: Process A7 (tau 606ms) completed a CPU burst; 11 bursts to go [Q A1 A3]
time 64270ms: Recalculated tau for process A7: old tau 606ms ==> new tau 62ms [Q A1 A3]
time 64270ms: Process A7 switching out of CPU; blocking on I/O until time 66857ms [Q A1 A3]
time 64276ms: Process A1 (tau 2120ms) started using the CPU for 36ms burst [Q A3]
time 64312ms: Process A1 (tau 2120ms) completed a CPU burst; 18 bursts to go [Q A3]
time 64312ms: Recalculated tau for process A1: old tau 2120ms ==> new tau 141ms [Q A3]
time 64312ms: Process A1 switching out of CPU; blocking on I/O until time 64952ms [Q A3]
time 64318ms: Process A3 (tau 3771ms) started using the CPU for 804ms burst [Q empty]
time 64633ms: Process A6 (tau 437ms) completed I/O; added to ready queue [Q A6]
time 64788ms: Process A0 (tau 1339ms) completed I/O; added to ready queue [Q A6 A0]
time 64952ms: Process A1 (tau 141ms) completed I/O; added to ready queue [Q A1 A6 A0]
time 65122ms: Process A3 (tau 3771ms) completed a CPU burst; 11 bursts to go [Q A1 A6 A0]
time 65122ms: Recalculated tau for process A3: old tau 3771ms ==> new tau 953ms [Q A1 A6 A0]
time 65122ms: Process A3 switching out of CPU; blocking on I/O until time 65190ms [Q A1 A6 A0]
time 65128ms: Process A1 (tau 141ms) started using the CPU for 4060ms burst [Q A6 A0]
time 65190ms: Process A3 (tau 953ms) completed I/O; added to ready queue [Q A6 A3 A0]
time 66857ms: Process A7 (tau 62ms) completed I/O; added to ready queue [Q A7 A6 A3 A0]
time 69188ms: Process A1 (tau 141ms) completed a CPU burst; 17 bursts to go [Q A7 A6 A3 A0]
time 69188ms: Recalculated tau for process A1: old tau 141ms ==> new tau 3865ms [Q A7 A6 A3 A0]
time 69188ms: Process A1 switching out of CPU; blocking on I/O until time 69281ms [Q A7 A6 A3 A0]
time 69194ms: Process A7 (tau 62ms) started using the CPU for 875ms burst [Q A6 A3 A0]
time 69281ms: Process A1 (tau 3865ms) completed I/O; added to ready queue [Q A6 A3 A0 A1]
time 70069ms: Process A7 (tau 62ms) completed a CPU burst; 10 bursts to go [Q A6 A3 A0 A1]
time 70069ms: Recalculated tau for process A7: old tau 62ms ==> new tau 835ms [Q A6 A3 A0 A1]
time 70069ms: Process A7 switching out of CPU; blocking on I/O until time 72424ms [Q A6 A3 A0 A1]
time 70075ms: Process A6 (tau 437ms) started using the CPU for 826ms burst [Q A3 A0 A1]
time 70901ms: Process A6 (tau 437ms) completed a CPU burst; 15 bursts to go [Q A3 A0 A1]
time 70901ms: Recalculated tau for process A6: old tau 437ms ==> new tau 807ms [Q A3 A0 A1]
time 70901ms: Process A6 switching out of CPU; blocking on I/O until time 73544ms [Q A3 A0 A1]
time 70907ms: Process A3 (tau 953ms) started using the CPU for 2564ms burst [Q A0 A1]
time 72424ms: Process A7 (tau 835ms) completed I/O; added to ready queue [Q A7 A0 A1]
time 73471ms: Process A3 (tau 953ms) completed a CPU burst; 10 bursts to go [Q A7 A0 A1]
time 73471ms: Recalculated tau for process A3: old tau 953ms ==> new tau 2484ms [Q A7 A0 A1]
time 73471ms: Process A3 switching out of CPU; blocking on I/O until time 73854ms [Q A7 A0 A1]
time 73477ms: Process A7 (tau 835ms) started using the CPU for 53ms burst [Q A0 A1]
time 73530ms: Process A7 (tau 835ms) completed a CPU burst; 9 bursts to go [Q A0 A1]
time 73530ms: Recalculated tau for process A7: old tau 835ms ==> new tau 93ms [Q A0 A1]
time 73530ms: Process A7 switching out of CPU; blocking on I/O until time 73773ms [Q A0 A1]
time 73536ms: Process A0 (tau 1339ms) started using the CPU for 1808ms burst [Q A1]
time 73544ms: Process A6 (tau 807ms) completed I/O; added to ready queue [Q A6 A1]
time 73773ms: Process A7 (tau 93ms) completed I/O; added to ready queue [Q A7 A6 A1]
time 73854ms: Process A3 (tau 2484ms) completed I/O; added to ready queue [Q A7 A6 A3 A1]
time 75344ms: Process A0 (tau 1339ms) completed a CPU burst; 22 bursts to go [Q A7 A6 A3 A1]
time 75344ms: Recalculated tau for process A0: old tau 1339ms ==> new tau 1785ms [Q A7 A6 A3 A1]
time 75344ms: Process A0 switching out of CPU; blocking on I/O until time 75496ms [Q A7 A6 A3 A1]
time 75350ms: Process A7 (tau 93ms) started using the CPU for 64ms burst [Q A6 A3 A1]
time 75414ms: Process A7 (tau 93ms) completed a CPU burst; 8 bursts to go [Q A6 A3 A1]
time 75414ms: Recalculated tau for process A7: old tau 93ms ==> new tau 66ms [Q A6 A3 A1]
time 75414ms: Process A7 switching out of CPU; blocking on I/O until time 78913ms [Q A6 A3 A1]
time 75420ms: Process A6 (tau 807ms) started using the CPU for 587ms burst [Q A3 A1]
time 75496ms: Process A0 (tau 1785ms) completed I/O; added to ready queue [Q A0 A3 A1]
time 76007ms: Process A6 (tau 807ms) completed a CPU burst; 14 bursts to go [Q A0 A3 A1]
time 76007ms: Recalculated tau for process A6: old tau 807ms ==> new tau 598ms [Q A0 A3 A1]
time 76007ms: Process A6 switching out of CPU; blocking on I/O until time 77930ms [Q A0 A3 A1]
time 76013ms: Process A0 (tau 1785ms) started using the CPU for 1808ms burst [Q A3 A1]
time 77821ms: Process A0 (tau 1785ms) completed a CPU burst; 21 bursts to go [Q A3 A1]
time 77821ms: Recalculated tau for process A0: old tau 1785ms ==> new tau 1807ms [Q A3 A1]
time 77821ms: Process A0 switching out of CPU; blocking on I/O until time 78090ms [Q A3 A1]
time 77827ms: Process A3 (tau 2484ms) started using the CPU for 3416ms burst [Q A1]
time 77930ms: Process A6 (tau 598ms) completed I/O; added to ready queue [Q A6 A1]
time 78090ms: Process A0 (tau 1807ms) completed I/O; added to ready queue [Q A6 A0 A1]
time 78913ms: Process A7 (tau 66ms) completed I/O; added to ready queue [Q A7 A6 A0 A1]
time 81243ms: Process A3 (tau 2484ms) completed a CPU burst; 9 bursts to go [Q A7 A6 A0 A1]
time 81243ms: Recalculated tau for process A3: old tau 2484ms ==> new tau 3370ms [Q A7 A6 A0 A1]
time 81243ms: Process A3 switching out of CPU; blocking on I/O until time 82135ms [Q A7 A6 A0 A1]
time 81249ms: Process A7 (tau 66ms) started using the CPU for 264ms burst [Q A6 A0 A1]
time 81513ms: Process A7 (tau 66ms) completed a CPU burst; 7 bursts to go [Q A6 A0 A1]
time 81513ms: Recalculated tau for process A7: old tau 66ms ==> new tau 255ms [Q A6 A0 A1]
time 81513ms: Process A7 switching out of CPU; blocking on I/O until time 82564ms [Q A6 A0 A1]
time 81519ms: Process A6 (tau 598ms) started using the CPU for 292ms burst [Q A0 A1]
time 81811ms: Process A6 (tau 598ms) completed a CPU burst; 13 bursts to go [Q A0 A1]
time 81811ms: Recalculated tau for process A6: old tau 598ms ==> new tau 308ms [Q A0 A1]
time 81811ms: Process A6 switching out of CPU; blocking on I/O until time 86294ms [Q A0 A1]
time 81817ms: Process A0 (tau 1807ms) started using the CPU for 848ms burst [Q A1]
time 82135ms: Process A3 (tau 3370ms) completed I/O; added to ready queue [Q A3 A1]
time 82564ms: Process A7 (tau 255ms) completed I/O; added to ready queue [Q A7 A3 A1]
time 82665ms: Process A0 (tau 1807ms) completed a CPU burst; 20 bursts to go [Q A7 A3 A1]
time 82665ms: Recalculated tau for process A0: old tau 1807ms ==> new tau 896ms [Q A7 A3 A1]
time 82665ms: Process A0 switching out of CPU; blocking on I/O until time 82743ms [Q A7 A3 A1]
time 82671ms: Process A7 (tau 255ms) started using the CPU for 228ms burst [Q A3 A1]
time 82743ms: Process A0 (tau 896ms) completed I/O; added to ready queue [Q A0 A3 A1]
time 82899ms: Process A7 (tau 255ms) completed a CPU burst; 6 bursts to go [Q A0 A3 A1]
time 82899ms: Recalculated tau for process A7: old tau 255ms ==> new tau 230ms [Q A0 A3 A1]
time 82899ms: Process A7 switching out of CPU; blocking on I/O until time 85166ms [Q A0 A3 A1]
time 82905ms: Process A0 (tau 896ms) started using the CPU for 3384ms burst [Q A3 A1]
time 85166ms: Process A7 (tau 230ms) completed I/O; added to ready queue [Q A7 A3 A1]
time 86289ms: Process A0 (tau 896ms) completed a CPU burst; 19 bursts to go [Q A7 A3 A1]
time 86289ms: Recalculated tau for process A0: old tau 896ms ==> new tau 3260ms [Q A7 A3 A1]
time 86289ms: Process A0 switching out of CPU; blocking on I/O until time 86309ms [Q A7 A3 A1]
time 86294ms: Process A6 (tau 308ms) completed I/O; added to ready queue [Q A6 A3 A1]
time 86295ms: Process A7 (tau 230ms) started using the CPU for 37ms burst [Q A6 A3 A1]
time 86309ms: Process A0 (tau 3260ms) completed I/O; added to ready queue [Q A6 A0 A3 A1]
time 86332ms: Process A7 (tau 230ms) completed a CPU burst; 5 bursts to go [Q A6 A0 A3 A1]
time 86332ms: Recalculated tau for process A7: old tau 230ms ==> new tau 47ms [Q A6 A0 A3 A1]
time 86332ms: Process A7 switching out of CPU; blocking on I/O until time 91831ms [Q A6 A0 A3 A1]
time 86338ms: Process A6 (tau 308ms) started using the CPU for 572ms burst [Q A0 A3 A1]
time 86910ms: Process A6 (tau 308ms) completed a CPU burst; 12 bursts to go [Q A0 A3 A1]
time 86910ms: Recalculated tau for process A6: old tau 308ms ==> new tau 559ms [Q A0 A3 A1]
time 86910ms: Process A6 switching out of CPU; blocking on I/O until time 87433ms [Q A0 A3 A1]
time 86916ms: Process A0 (tau 3260ms) started using the CPU for 104ms burst [Q A3 A1]
time 87020ms: Process A0 (tau 3260ms) completed a CPU burst; 18 bursts to go [Q A3 A1]
time 87020ms: Recalculated tau for process A0: old tau 3260ms ==> new tau 262ms [Q A3 A1]
time 87020ms: Process A0 switching out of CPU; blocking on I/O until time 87451ms [Q A3 A1]
time 87026ms: Process A3 (tau 3370ms) started using the CPU for 3756ms burst [Q A1]
time 87433ms: Process A6 (tau 559ms) completed I/O; added to ready queue [Q A6 A1]
time 87451ms: Process A0 (tau 262ms) completed I/O; added to ready queue [Q A0 A6 A1]
time 90782ms: Process A3 (tau 3370ms) completed a CPU burst; 8 bursts to go [Q A0 A6 A1]
time 90782ms: Recalculated tau for process A3: old tau 3370ms ==> new tau 3737ms [Q A0 A6 A1]
time 90782ms: Process A3 switching out of CPU; blocking on I/O until time 91436ms [Q A0 A6 A1]
time 90788ms: Process A0 (tau 262ms) started using the CPU for 3924ms burst [Q A6 A1]
time 91436ms: Process A3 (tau 3737ms) completed I/O; added to ready queue [Q A6 A3 A1]
time 91831ms: Process A7 (tau 47ms) completed I/O; added to ready queue [Q A7 A6 A3 A1]
time 94712ms: Process A0 (tau 262ms) completed a CPU burst; 17 bursts to go [Q A7 A6 A3 A1]
time 94712ms: Recalculated tau for process A0: old tau 262ms ==> new tau 3741ms [Q A7 A6 A3 A1]
time 94712ms: Process A0 switching out of CPU; blocking on I/O until time 95382ms [Q A7 A6 A3 A1]
time 94718ms: Process A7 (tau 47ms) started using the CPU for 364ms burst [Q A6 A3 A1]
time 95082ms: Process A7 (tau 47ms) completed a CPU burst; 4 bursts to go [Q A6 A3 A1]
time 95082ms: Recalculated tau for process A7: old tau 47ms ==> new tau 349ms [Q A6 A3 A1]
time 95082ms: Process A7 switching out of CPU; blocking on I/O until time 99397ms [Q A6 A3 A1]
time 95088ms: Process A6 (tau 559ms) started using the CPU for 494ms burst [Q A3 A1]
time 95382ms: Process A0 (tau 3741ms) completed I/O; added to ready queue [Q A3 A0 A1]
time 95582ms: Process A6 (tau 559ms) completed a CPU burst; 11 bursts to go [Q A3 A0 A1]
time 95582ms: Recalculated tau for process A6: old tau 559ms ==> new tau 498ms [Q A3 A0 A1]
time 95582ms: Process A6 switching out of CPU; blocking on I/O until time 102673ms [Q A3 A0 A1]
time 95588ms: Process A3 (tau 3737ms) started using the CPU for 3864ms burst [Q A0 A1]
time 99397ms: Process A7 (tau 349ms) completed I/O; added to ready queue [Q A7 A0 A1]
time 99452ms: Process A3 (tau 3737ms) completed a CPU burst; 7 bursts to go [Q A7 A0 A1]
time 99452ms: Recalculated tau for process A3: old tau 3737ms ==> new tau 3858ms [Q A7 A0 A1]
time 99452ms: Process A3 switching out of CPU; blocking on I/O until time 99878ms [Q A7 A0 A1]
time 99458ms: Process A7 (tau 349ms) started using the CPU for 278ms burst [Q A0 A1]
time 99736ms: Process A7 (tau 349ms) completed a CPU burst; 3 bursts to go [Q A0 A1]
time 99736ms: Recalculated tau for process A7: old tau 349ms ==> new tau 282ms [Q A0 A1]
time 99736ms: Process A7 switching out of CPU; blocking on I/O until time 102251ms [Q A0 A1]
time 99742ms: Process A0 (tau 3741ms) started using the CPU for 3388ms burst [Q A1]
time 99878ms: Process A3 (tau 3858ms) completed I/O; added to ready queue [Q A3 A1]
time 102251ms: Process A7 (tau 282ms) completed I/O; added to ready queue [Q A7 A3 A1]
time 102673ms: Process A6 (tau 498ms) completed I/O; added to ready queue [Q A7 A6 A3 A1]
time 103130ms: Process A0 (tau 3741ms) completed a CPU burst; 16 bursts to go [Q A7 A6 A3 A1]
time 103130ms: Recalculated tau for process A0: old tau 3741ms ==> new tau 3406ms [Q A7 A6 A3 A1]
time 103130ms: Process A0 switching out of CPU; blocking on I/O until time 103227ms [Q A7 A6 A3 A1]
time 103136ms: Process A7 (tau 282ms) started using the CPU for 23ms burst [Q A6 A3 A1]
time 103159ms: Process A7 (tau 282ms) completed a CPU burst; 2 bursts to go [Q A6 A3 A1]
time 103159ms: Recalculated tau for process A7: old tau 282ms ==> new tau 36ms [Q A6 A3 A1]
time 103159ms: Process A7 switching out of CPU; blocking on I/O until time 111042ms [Q A6 A3 A1]
time 103165ms: Process A6 (tau 498ms) started using the CPU for 19ms burst [Q A3 A1]
time 103184ms: Process A6 (tau 498ms) completed a CPU burst; 10 bursts to go [Q A3 A1]
time 103184ms: Recalculated tau for process A6: old tau 498ms ==> new tau 43ms [Q A3 A1]
time 103184ms: Process A6 switching out of CPU; blocking on I/O until time 107403ms [Q A3 A1]
time 103190ms: Process A3 (tau 3858ms) started using the CPU for 1144ms burst [Q A1]
time 103227ms: Process A0 (tau 3406ms) completed I/O; added to ready queue [Q A0 A1]
time 104334ms: Process A3 (tau 3858ms) completed a CPU burst; 6 bursts to go [Q A0 A1]
time 104334ms: Recalculated tau for process A3: old tau 3858ms ==> new tau 1280ms [Q A0 A1]
time 104334ms: Process A3 switching out of CPU; blocking on I/O until time 104487ms [Q A0 A1]
time 104340ms: Process A0 (tau 3406ms) started using the CPU for 100ms burst [Q A1]
time 104440ms: Process A0 (tau 3406ms) completed a CPU burst; 15 bursts to go [Q A1]
time 104440ms: Recalculated tau for process A0: old tau 3406ms ==> new tau 266ms [Q A1]
time 104440ms: Process A0 switching out of CPU; blocking on I/O until time 104930ms [Q A1]
time 104446ms: Process A1 (tau 3865ms) started using the CPU for 3904ms burst [Q empty]
time 104487ms: Process A3 (tau 1280ms) completed I/O; added to ready queue [Q A3]
time 104930ms: Process A0 (tau 266ms) completed I/O; added to ready queue [Q A0 A3]
time 107403ms: Process A6 (tau 43ms) completed I/O; added to ready queue [Q A6 A0 A3]
time 108350ms: Process A1 (tau 3865ms) completed a CPU burst; 16 bursts to go [Q A6 A0 A3]
time 108350ms: Recalculated tau for process A1: old tau 3865ms ==> new tau 3903ms [Q A6 A0 A3]
time 108350ms: Process A1 switching out of CPU; blocking on I/O until time 108887ms [Q A6 A0 A3]
time 108356ms: Process A6 (tau 43ms) started using the CPU for 355ms burst [Q A0 A3]
time 108711ms: Process A6 (tau 43ms) completed a CPU burst; 9 bursts to go [Q A0 A3]
time 108711ms: Recalculated tau for process A6: old tau 43ms ==> new tau 340ms [Q A0 A3]
time 108711ms: Process A6 switching out of CPU; blocking on I/O until time 111682ms [Q A0 A3]
time 108717ms: Process A0 (tau 266ms) started using the CPU for 3868ms burst [Q A3]
time 108887ms: Process A1 (tau 3903ms) completed I/O; added to ready queue [Q A3 A1]
time 111042ms: Process A7 (tau 36ms) completed I/O; added to ready queue [Q A7 A3 A1]
time 111682ms: Process A6 (tau 340ms) completed I/O; added to ready queue [Q A7 A6 A3 A1]
time 112585ms: Process A0 (tau 266ms) completed a CPU burst; 14 bursts to go [Q A7 A6 A3 A1]
time 112585ms: Recalculated tau for process A0: old tau 266ms ==> new tau 3688ms [Q A7 A6 A3 A1]
time 112585ms: Process A0 switching out of CPU; blocking on I/O until time 112700ms [Q A7 A6 A3 A1]
time 112591ms: Process A7 (tau 36ms) started using the CPU for 188ms burst [Q A6 A3 A1]
time 112700ms: Process A0 (tau 3688ms) completed I/O; added to ready queue [Q A6 A3 A0 A1]
time 112779ms: Process A7 (tau 36ms) completed a CPU burst; 1 burst to go [Q A6 A3 A0 A1]
time 112779ms: Recalculated tau for process A7: old tau 36ms ==> new tau 181ms [Q A6 A3 A0 A1]
time 112779ms: Process A7 switching out of CPU; blocking on I/O until time 116678ms [Q A6 A3 A0 A1]
time 112785ms: Process A6 (tau 340ms) started using the CPU for 81ms burst [Q A3 A0 A1]
time 112866ms: Process A6 (tau 340ms) completed a CPU burst; 8 bursts to go [Q A3 A0 A1]
time 112866ms: Recalculated tau for process A6: old tau 340ms ==> new tau 94ms [Q A3 A0 A1]
time 112866ms: Process A6 switching out of CPU; blocking on I/O until time 120309ms [Q A3 A0 A1]
time 112872ms: Process A3 (tau 1280ms) started using the CPU for 492ms burst [Q A0 A1]
time 113364ms: Process A3 (tau 1280ms) completed a CPU burst; 5 bursts to go [Q A0 A1]
time 113364ms: Recalculated tau for process A3: old tau 1280ms ==> new tau 532ms [Q A0 A1]
time 113364ms: Process A3 switching out of CPU; blocking on I/O until time 113735ms [Q A0 A1]
time 113370ms: Process A0 (tau 3688ms) started using the CPU for 1516ms burst [Q A1]
time 113735ms: Process A3 (tau 532ms) completed I/O; added to ready queue [Q A3 A1]
time 114886ms: Process A0 (tau 3688ms) completed a CPU burst; 13 bursts to go [Q A3 A1]
time 114886ms: Recalculated tau for process A0: old tau 3688ms ==> new tau 1625ms [Q A3 A1]
time 114886ms: Process A0 switching out of CPU; blocking on I/O until time 115200ms [Q A3 A1]
time 114892ms: Process A3 (tau 532ms) started using the CPU for 2704ms burst [Q A1]
time 115200ms: Process A0 (tau 1625ms) completed I/O; added to ready queue [Q A0 A1]
time 116678ms: Process A7 (tau 181ms) completed I/O; added to ready queue [Q A7 A0 A1]
time 117596ms: Process A3 (tau 532ms) completed a CPU burst; 4 bursts to go [Q A7 A0 A1]
time 117596ms: Recalculated tau for process A3: old tau 532ms ==> new tau 2596ms [Q A7 A0 A1]
time 117596ms: Process A3 switching out of CPU; blocking on I/O until time 117775ms [Q A7 A0 A1]
time 117602ms: Process A7 (tau 181ms) started using the CPU for 214ms burst [Q A0 A1]
time 117775ms: Process A3 (tau 2596ms) completed I/O; added to ready queue [Q A0 A3 A1]
time 117816ms: Process A7 terminated [Q A0 A3 A1]
time 117822ms: Process A0 (tau 1625ms) started using the CPU for 1260ms burst [Q A3 A1]
time 119082ms: Process A0 (tau 1625ms) completed a CPU burst; 12 bursts to go [Q A3 A1]
time 119082ms: Recalculated tau for process A0: old tau 1625ms ==> new tau 1279ms [Q A3 A1]
time 119082ms: Process A0 switching out of CPU; blocking on I/O until time 119498ms [Q A3 A1]
time 119088ms: Process A3 (tau 2596ms) started using the CPU for 316ms burst [Q A1]
time 119404ms: Process A3 (tau 2596ms) completed a CPU burst; 3 bursts to go [Q A1]
time 119404ms: Recalculated tau for process A3: old tau 2596ms ==> new tau 431ms [Q A1]
time 119404ms: Process A3 switching out of CPU; blocking on I/O until time 120075ms [Q A1]
time 119410ms: Process A1 (tau 3903ms) started using the CPU for 1488ms burst [Q empty]
time 119498ms: Process A0 (tau 1279ms) completed I/O; added to ready queue [Q A0]
time 120075ms: Process A3 (tau 431ms) completed I/O; added to ready queue [Q A3 A0]
time 120309ms: Process A6 (tau 94ms) completed I/O; added to ready queue [Q A6 A3 A0]
time 120898ms: Process A1 (tau 3903ms) completed a CPU burst; 15 bursts to go [Q A6 A3 A0]
time 120898ms: Recalculated tau for process A1: old tau 3903ms ==> new tau 1609ms [Q A6 A3 A0]
time 120898ms: Process A1 switching out of CPU; blocking on I/O until time 121305ms [Q A6 A3 A0]
time 120904ms: Process A6 (tau 94ms) started using the CPU for 25ms burst [Q A3 A0]
time 120929ms: Process A6 (tau 94ms) completed a CPU burst; 7 bursts to go [Q A3 A0]
time 120929ms: Recalculated tau for process A6: old tau 94ms ==> new tau 29ms [Q A3 A0]
time 120929ms: Process A6 switching out of CPU; blocking on I/O until time 121876ms [Q A3 A0]
time 120935ms: Process A3 (tau 431ms) started using the CPU for 204ms burst [Q A0]
time 121139ms: Process A3 (tau 431ms) completed a CPU burst; 2 bursts to go [Q A0]
time 121139ms: Recalculated tau for process A3: old tau 431ms ==> new tau 216ms [Q A0]
time 121139ms: Process A3 switching out of CPU; blocking on I/O until time 121474ms [Q A0]
time 121145ms: Process A0 (tau 1279ms) started using the CPU for 728ms burst [Q empty]
time 121305ms: Process A1 (tau 1609ms) completed I/O; added to ready queue [Q A1]
time 121474ms: Process A3 (tau 216ms) completed I/O; added to ready queue [Q A3 A1]
time 121873ms: Process A0 (tau 1279ms) completed a CPU burst; 11 bursts to go [Q A3 A1]
time 121873ms: Recalculated tau for process A0: old tau 1279ms ==> new tau 756ms [Q A3 A1]
time 121873ms: Process A0 switching out of CPU; blocking on I/O until time 122649ms [Q A3 A1]
time 121876ms: Process A6 (tau 29ms) completed I/O; added to ready queue [Q A6 A3 A1]
time 121879ms: Process A6 (tau 29ms) started using the CPU for 445ms burst [Q A3 A1]
time 122324ms: Process A6 (tau 29ms) completed a CPU burst; 6 bursts to go [Q A3 A1]
time 122324ms: Recalculated tau for process A6: old tau 29ms ==> new tau 425ms [Q A3 A1]
time 122324ms: Process A6 switching out of CPU; blocking on I/O until time 125535ms [Q A3 A1]
time 122330ms: Process A3 (tau 216ms) started using the CPU for 2328ms burst [Q A1]
time 122649ms: Process A0 (tau 756ms) completed I/O; added to ready queue [Q A0 A1]
time 124658ms: Process A3 (tau 216ms) completed a CPU burst; 1 burst to go [Q A0 A1]
time 124658ms: Recalculated tau for process A3: old tau 216ms ==> new tau 2223ms [Q A0 A1]
time 124658ms: Process A3 switching out of CPU; blocking on I/O until time 125557ms [Q A0 A1]
time 124664ms: Process A0 (tau 756ms) started using the CPU for 2568ms burst [Q A1]
time 125535ms: Process A6 (tau 425ms) completed I/O; added to ready queue [Q A6 A1]
time 125557ms: Process A3 (tau 2223ms) completed I/O; added to ready queue [Q A6 A1 A3]
time 127232ms: Process A0 (tau 756ms) completed a CPU burst; 10 bursts to go [Q A6 A1 A3]
time 127232ms: Recalculated tau for process A0: old tau 756ms ==> new tau 2478ms [Q A6 A1 A3]
time 127232ms: Process A0 switching out of CPU; blocking on I/O until time 127583ms [Q A6 A1 A3]
time 127238ms: Process A6 (tau 425ms) started using the CPU for 35ms burst [Q A1 A3]
time 127273ms: Process A6 (tau 425ms) completed a CPU burst; 5 bursts to go [Q A1 A3]
time 127273ms: Recalculated tau for process A6: old tau 425ms ==> new tau 55ms [Q A1 A3]
time 127273ms: Process A6 switching out of CPU; blocking on I/O until time 130316ms [Q A1 A3]
time 127279ms: Process A1 (tau 1609ms) started using the CPU for 1080ms burst [Q A3]
time 127583ms: Process A0 (tau 2478ms) completed I/O; added to ready queue [Q A3 A0]
time 128359ms: Process A1 (tau 1609ms) completed a CPU burst; 14 bursts to go [Q A3 A0]
time 128359ms: Recalculated tau for process A1: old tau 1609ms ==> new tau 1107ms [Q A3 A0]
time 128359ms: Process A1 switching out of CPU; blocking on I/O until time 128413ms [Q A3 A0]
time 128365ms: Process A3 (tau 2223ms) started using the CPU for 2760ms burst [Q A0]
time 128413ms: Process A1 (tau 1107ms) completed I/O; added to ready queue [Q A1 A0]
time 130316ms: Process A6 (tau 55ms) completed I/O; added to ready queue [Q A6 A1 A0]
time 131125ms: Process A3 terminated [Q A6 A1 A0]
time 131131ms: Process A6 (tau 55ms) started using the CPU for 245ms burst [Q A1 A0]
time 131376ms: Process A6 (tau 55ms) completed a CPU burst; 4 bursts to go [Q A1 A0]
time 131376ms: Recalculated tau for process A6: old tau 55ms ==> new tau 236ms [Q A1 A0]
time 131376ms: Process A6 switching out of CPU; blocking on I/O until time 138619ms [Q A1 A0]
time 131382ms: Process A1 (tau 1107ms) started using the CPU for 916ms burst [Q A0]
time 132298ms: Process A1 (tau 1107ms) completed a CPU burst; 13 bursts to go [Q A0]
time 132298ms: Recalculated tau for process A1: old tau 1107ms ==> new tau 926ms [Q A0]
time 132298ms: Process A1 switching out of CPU; blocking on I/O until time 132372ms [Q A0]
time 132304ms: Process A0 (tau 2478ms) started using the CPU for 1220ms burst [Q empty]
time 132372ms: Process A1 (tau 926ms) completed I/O; added to ready queue [Q A1]
time 133524ms: Process A0 (tau 2478ms) completed a CPU burst; 9 bursts to go [Q A1]
time 133524ms: Recalculated tau for process A0: old tau 2478ms ==> new tau 1283ms [Q A1]
time 133524ms: Process A0 switching out of CPU; blocking on I/O until time 134410ms [Q A1]
time 133530ms: Process A1 (tau 926ms) started using the CPU for 3724ms burst [Q empty]
time 134410ms: Process A0 (tau 1283ms) completed I/O; added to ready queue [Q A0]
time 137254ms: Process A1 (tau 926ms) completed a CPU burst; 12 bursts to go [Q A0]
time 137254ms: Recalculated tau for process A1: old tau 926ms ==> new tau 3585ms [Q A0]
time 137254ms: Process A1 switching out of CPU; blocking on I/O until time 137368ms [Q A0]
time 137260ms: Process A0 (tau 1283ms) started using the CPU for 2296ms burst [Q empty]
time 137368ms: Process A1 (tau 3585ms) completed I/O; added to ready queue [Q A1]
time 138619ms: Process A6 (tau 236ms) completed I/O; added to ready queue [Q A6 A1]
time 139556ms: Process A0 (tau 1283ms) completed a CPU burst; 8 bursts to go [Q A6 A1]
time 139556ms: Recalculated tau for process A0: old tau 1283ms ==> new tau 2246ms [Q A6 A1]
time 139556ms: Process A0 switching out of CPU; blocking on I/O until time 140223ms [Q A6 A1]
time 139562ms: Process A6 (tau 236ms) started using the CPU for 732ms burst [Q A1]
time 140223ms: Process A0 (tau 2246ms) completed I/O; added to ready queue [Q A0 A1]
time 140294ms: Process A6 (tau 236ms) completed a CPU burst; 3 bursts to go [Q A0 A1]
time 140294ms: Recalculated tau for process A6: old tau 236ms ==> new tau 708ms [Q A0 A1]
time 140294ms: Process A6 switching out of CPU; blocking on I/O until time 142361ms [Q A0 A1]
time 140300ms: Process A0 (tau 2246ms) started using the CPU for 3268ms burst [Q A1]
time 142361ms: Process A6 (tau 708ms) completed I/O; added to ready queue [Q A6 A1]
time 143568ms: Process A0 (tau 2246ms) completed a CPU burst; 7 bursts to go [Q A6 A1]
time 143568ms: Recalculated tau for process A0: old tau 2246ms ==> new tau 3217ms [Q A6 A1]
